Workbook
Name Latest_7days: #REF!
Name BE_Antwerpen__DEPPROD: #REF!

Sheet Graphs
C1: World export prices FOB
C2: Update: | E2: =Data!$A$4+1 -> 45967
C4: Wheat - EU Rouen (grade 1) | E4: Wheat - US Gulf (HRW) | G4: Wheat - Ukraine (milling) | I4: Select price from here (drop-down list) | K4: Select price from here (drop-down list) | O4: Maize - US Gulf (3YC) | Q4: Maize - EU Bordeaux | S4: Maize - Black Sea (feed) | U4: Select price from here (drop-down list) | W4: Select price from here (drop-down list) | CL4: =C4 -> Wheat - EU Rouen (grade 1) | CM4: =E4 -> Wheat - US Gulf (HRW) | CN4: =G4 -> Wheat - Ukraine (milling) | CO4: =I4 -> Select price from here (drop-down list) | CP4: =K4 -> Select price from here (drop-down list) | CR4: =O4 -> Maize - US Gulf (3YC) | CS4: =Q4 -> Maize - EU Bordeaux | CT4: =S4 -> Maize - Black Sea (feed) | CU4: =U4 -> Select price from here (drop-down list) | CV4: =W4 -> Select price from here (drop-down list)
CK5: =Data!A4 -> 45966 | CL5: {=IF(INDEX(Data!$B$4:$L$947,MATCH(Graphs!$CK5,Data!$A$4:$A$947,0),MATCH(Graphs!CL$4,Data!$B$3:$L$3,0))="n.q.",NA(),INDEX(Data!$B$4:$L$947,MATCH(Graphs!$CK5,Data!$A$4:$A$947,0),MATCH(Graphs!CL$4,Data!$B$3:$L$3,0)))} -> 231.41 | CM5: {=IF(INDEX(Data!$B$4:$L$947,MATCH(Graphs!$CK5,Data!$A$4:$A$947,0),MATCH(Graphs!CM$4,Data!$B$3:$L$3,0))="n.q.",NA(),INDEX(Data!$B$4:$L$947,MATCH(Graphs!$CK5,Data!$A$4:$A$947,0),MATCH(Graphs!CM$4,Data!$B$3:$L$3,0)))} -> 249.86 | CN5: {=IF(INDEX(Data!$B$4:$L$947,MATCH(Graphs!$CK5,Data!$A$4:$A$947,0),MATCH(Graphs!CN$4,Data!$B$3:$L$3,0))="n.q.",NA(),INDEX(Data!$B$4:$L$947,MATCH(Graphs!$CK5,Data!$A$4:$A$947,0),MATCH(Graphs!CN$4,Data!$B$3:$L$3,0)))} -> 220 | CO5: {=IF(INDEX(Data!$B$4:$L$947,MATCH(Graphs!$CK5,Data!$A$4:$A$947,0),MATCH(Graphs!CO$4,Data!$B$3:$L$3,0))="n.q.",NA(),INDEX(Data!$B$4:$L$947,MATCH(Graphs!$CK5,Data!$A$4:$A$947,0),MATCH(Graphs!CO$4,Data!$B$3:$L$3,0)))} -> #N/A | CP5: {=IF(INDEX(Data!$B$4:$L$947,MATCH(Graphs!$CK5,Data!$A$4:$A$947,0),MATCH(Graphs!CP$4,Data!$B$3:$L$3,0))="n.q.",NA(),INDEX(Data!$B$4:$L$947,MATCH(Graphs!$CK5,Data!$A$4:$A$947,0),MATCH(Graphs!CP$4,Data!$B$3:$L$3,0)))} -> #N/A | CR5: {=IF(INDEX(Data!$P$4:$Z$947,MATCH(Graphs!$CK5,Data!$A$4:$A$947,0),MATCH(Graphs!CR$4,Data!$P$3:$Z$3,0))="n.q.",NA(),INDEX(Data!$P$4:$Z$947,MATCH(Graphs!$CK5,Data!$A$4:$A$947,0),MATCH(Graphs!CR$4,Data!$P$3:$Z$3,0)))} -> 181.17718 | CS5: {=IF(INDEX(Data!$P$4:$Z$947,MATCH(Graphs!$CK5,Data!$A$4:$A$947,0),MATCH(Graphs!CS$4,Data!$P$3:$Z$3,0))="n.q.",NA(),INDEX(Data!$P$4:$Z$947,MATCH(Graphs!$CK5,Data!$A$4:$A$947,0),MATCH(Graphs!CS$4,Data!$P$3:$Z$3,0)))} -> #N/A | CT5: {=IF(INDEX(Data!$P$4:$Z$947,MATCH(Graphs!$CK5,Data!$A$4:$A$947,0),MATCH(Graphs!CT$4,Data!$P$3:$Z$3,0))="n.q.",NA(),INDEX(Data!$P$4:$Z$947,MATCH(Graphs!$CK5,Data!$A$4:$A$947,0),MATCH(Graphs!CT$4,Data!$P$3:$Z$3,0)))} -> 188.14188 | CU5: {=IF(INDEX(Data!$P$4:$Z$947,MATCH(Graphs!$CK5,Data!$A$4:$A$947,0),MATCH(Graphs!CU$4,Data!$P$3:$Z$3,0))="n.q.",NA(),INDEX(Data!$P$4:$Z$947,MATCH(Graphs!$CK5,Data!$A$4:$A$947,0),MATCH(Graphs!CU$4,Data!$P$3:$Z$3,0)))} -> #N/A | CV5: {=IF(INDEX(Data!$P$4:$Z$947,MATCH(Graphs!$CK5,Data!$A$4:$A$947,0),MATCH(Graphs!CV$4,Data!$P$3:$Z$3,0))="n.q.",NA(),INDEX(Data!$P$4:$Z$947,MATCH(Graphs!$CK5,Data!$A$4:$A$947,0),MATCH(Graphs!CV$4,Data!$P$3:$Z$3,0)))} -> #N/A
CK6: =Data!A5 -> 45959 | CL6: {=IF(INDEX(Data!$B$4:$L$947,MATCH(Graphs!$CK6,Data!$A$4:$A$947,0),MATCH(Graphs!CL$4,Data!$B$3:$L$3,0))="n.q.",NA(),INDEX(Data!$B$4:$L$947,MATCH(Graphs!$CK6,Data!$A$4:$A$947,0),MATCH(Graphs!CL$4,Data!$B$3:$L$3,0)))} -> 230.31 | CM6: {=IF(INDEX(Data!$B$4:$L$947,MATCH(Graphs!$CK6,Data!$A$4:$A$947,0),MATCH(Graphs!CM$4,Data!$B$3:$L$3,0))="n.q.",NA(),INDEX(Data!$B$4:$L$947,MATCH(Graphs!$CK6,Data!$A$4:$A$947,0),MATCH(Graphs!CM$4,Data!$B$3:$L$3,0)))} -> 241.68 | CN6: {=IF(INDEX(Data!$B$4:$L$947,MATCH(Graphs!$CK6,Data!$A$4:$A$947,0),MATCH(Graphs!CN$4,Data!$B$3:$L$3,0))="n.q.",NA(),INDEX(Data!$B$4:$L$947,MATCH(Graphs!$CK6,Data!$A$4:$A$947,0),MATCH(Graphs!CN$4,Data!$B$3:$L$3,0)))} -> 219 | CO6: {=IF(INDEX(Data!$B$4:$L$947,MATCH(Graphs!$CK6,Data!$A$4:$A$947,0),MATCH(Graphs!CO$4,Data!$B$3:$L$3,0))="n.q.",NA(),INDEX(Data!$B$4:$L$947,MATCH(Graphs!$CK6,Data!$A$4:$A$947,0),MATCH(Graphs!CO$4,Data!$B$3:$L$3,0)))} -> #N/A | CP6: {=IF(INDEX(Data!$B$4:$L$947,MATCH(Graphs!$CK6,Data!$A$4:$A$947,0),MATCH(Graphs!CP$4,Data!$B$3:$L$3,0))="n.q.",NA(),INDEX(Data!$B$4:$L$947,MATCH(Graphs!$CK6,Data!$A$4:$A$947,0),MATCH(Graphs!CP$4,Data!$B$3:$L$3,0)))} -> #N/A | CR6: {=IF(INDEX(Data!$P$4:$Z$947,MATCH(Graphs!$CK6,Data!$A$4:$A$947,0),MATCH(Graphs!CR$4,Data!$P$3:$Z$3,0))="n.q.",NA(),INDEX(Data!$P$4:$Z$947,MATCH(Graphs!$CK6,Data!$A$4:$A$947,0),MATCH(Graphs!CR$4,Data!$P$3:$Z$3,0)))} -> 178.51489 | CS6: {=IF(INDEX(Data!$P$4:$Z$947,MATCH(Graphs!$CK6,Data!$A$4:$A$947,0),MATCH(Graphs!CS$4,Data!$P$3:$Z$3,0))="n.q.",NA(),INDEX(Data!$P$4:$Z$947,MATCH(Graphs!$CK6,Data!$A$4:$A$947,0),MATCH(Graphs!CS$4,Data!$P$3:$Z$3,0)))} -> #N/A | CT6: {=IF(INDEX(Data!$P$4:$Z$947,MATCH(Graphs!$CK6,Data!$A$4:$A$947,0),MATCH(Graphs!CT$4,Data!$P$3:$Z$3,0))="n.q.",NA(),INDEX(Data!$P$4:$Z$947,MATCH(Graphs!$CK6,Data!$A$4:$A$947,0),MATCH(Graphs!CT$4,Data!$P$3:$Z$3,0)))} -> 184.99398 | CU6: {=IF(INDEX(Data!$P$4:$Z$947,MATCH(Graphs!$CK6,Data!$A$4:$A$947,0),MATCH(Graphs!CU$4,Data!$P$3:$Z$3,0))="n.q.",NA(),INDEX(Data!$P$4:$Z$947,MATCH(Graphs!$CK6,Data!$A$4:$A$947,0),MATCH(Graphs!CU$4,Data!$P$3:$Z$3,0)))} -> #N/A | CV6: {=IF(INDEX(Data!$P$4:$Z$947,MATCH(Graphs!$CK6,Data!$A$4:$A$947,0),MATCH(Graphs!CV$4,Data!$P$3:$Z$3,0))="n.q.",NA(),INDEX(Data!$P$4:$Z$947,MATCH(Graphs!$CK6,Data!$A$4:$A$947,0),MATCH(Graphs!CV$4,Data!$P$3:$Z$3,0)))} -> #N/A
CK7: =Data!A6 -> 45952 | CL7: {=IF(INDEX(Data!$B$4:$L$947,MATCH(Graphs!$CK7,Data!$A$4:$A$947,0),MATCH(Graphs!CL$4,Data!$B$3:$L$3,0))="n.q.",NA(),INDEX(Data!$B$4:$L$947,MATCH(Graphs!$CK7,Data!$A$4:$A$947,0),MATCH(Graphs!CL$4,Data!$B$3:$L$3,0)))} -> 227.1 | CM7: {=IF(INDEX(Data!$B$4:$L$947,MATCH(Graphs!$CK7,Data!$A$4:$A$947,0),MATCH(Graphs!CM$4,Data!$B$3:$L$3,0))="n.q.",NA(),INDEX(Data!$B$4:$L$947,MATCH(Graphs!$CK7,Data!$A$4:$A$947,0),MATCH(Graphs!CM$4,Data!$B$3:$L$3,0)))} -> 227.26 | CN7: {=IF(INDEX(Data!$B$4:$L$947,MATCH(Graphs!$CK7,Data!$A$4:$A$947,0),MATCH(Graphs!CN$4,Data!$B$3:$L$3,0))="n.q.",NA(),INDEX(Data!$B$4:$L$947,MATCH(Graphs!$CK7,Data!$A$4:$A$947,0),MATCH(Graphs!CN$4,Data!$B$3:$L$3,0)))} -> 219 | CO7: {=IF(INDEX(Data!$B$4:$L$947,MATCH(Graphs!$CK7,Data!$A$4:$A$947,0),MATCH(Graphs!CO$4,Data!$B$3:$L$3,0))="n.q.",NA(),INDEX(Data!$B$4:$L$947,MATCH(Graphs!$CK7,Data!$A$4:$A$947,0),MATCH(Graphs!CO$4,Data!$B$3:$L$3,0)))} -> #N/A | CP7: {=IF(INDEX(Data!$B$4:$L$947,MATCH(Graphs!$CK7,Data!$A$4:$A$947,0),MATCH(Graphs!CP$4,Data!$B$3:$L$3,0))="n.q.",NA(),INDEX(Data!$B$4:$L$947,MATCH(Graphs!$CK7,Data!$A$4:$A$947,0),MATCH(Graphs!CP$4,Data!$B$3:$L$3,0)))} -> #N/A | CR7: {=IF(INDEX(Data!$P$4:$Z$947,MATCH(Graphs!$CK7,Data!$A$4:$A$947,0),MATCH(Graphs!CR$4,Data!$P$3:$Z$3,0))="n.q.",NA(),INDEX(Data!$P$4:$Z$947,MATCH(Graphs!$CK7,Data!$A$4:$A$947,0),MATCH(Graphs!CR$4,Data!$P$3:$Z$3,0)))} -> #N/A | CS7: {=IF(INDEX(Data!$P$4:$Z$947,MATCH(Graphs!$CK7,Data!$A$4:$A$947,0),MATCH(Graphs!CS$4,Data!$P$3:$Z$3,0))="n.q.",NA(),INDEX(Data!$P$4:$Z$947,MATCH(Graphs!$CK7,Data!$A$4:$A$947,0),MATCH(Graphs!CS$4,Data!$P$3:$Z$3,0)))} -> #N/A | CT7: {=IF(INDEX(Data!$P$4:$Z$947,MATCH(Graphs!$CK7,Data!$A$4:$A$947,0),MATCH(Graphs!CT$4,Data!$P$3:$Z$3,0))="n.q.",NA(),INDEX(Data!$P$4:$Z$947,MATCH(Graphs!$CK7,Data!$A$4:$A$947,0),MATCH(Graphs!CT$4,Data!$P$3:$Z$3,0)))} -> #N/A | CU7: {=IF(INDEX(Data!$P$4:$Z$947,MATCH(Graphs!$CK7,Data!$A$4:$A$947,0),MATCH(Graphs!CU$4,Data!$P$3:$Z$3,0))="n.q.",NA(),INDEX(Data!$P$4:$Z$947,MATCH(Graphs!$CK7,Data!$A$4:$A$947,0),MATCH(Graphs!CU$4,Data!$P$3:$Z$3,0)))} -> #N/A | CV7: {=IF(INDEX(Data!$P$4:$Z$947,MATCH(Graphs!$CK7,Data!$A$4:$A$947,0),MATCH(Graphs!CV$4,Data!$P$3:$Z$3,0))="n.q.",NA(),INDEX(Data!$P$4:$Z$947,MATCH(Graphs!$CK7,Data!$A$4:$A$947,0),MATCH(Graphs!CV$4,Data!$P$3:$Z$3,0)))} -> #N/A
CK8: =Data!A7 -> 45945 | CL8: {=IF(INDEX(Data!$B$4:$L$947,MATCH(Graphs!$CK8,Data!$A$4:$A$947,0),MATCH(Graphs!CL$4,Data!$B$3:$L$3,0))="n.q.",NA(),INDEX(Data!$B$4:$L$947,MATCH(Graphs!$CK8,Data!$A$4:$A$947,0),MATCH(Graphs!CL$4,Data!$B$3:$L$3,0)))} -> 226.42 | CM8: {=IF(INDEX(Data!$B$4:$L$947,MATCH(Graphs!$CK8,Data!$A$4:$A$947,0),MATCH(Graphs!CM$4,Data!$B$3:$L$3,0))="n.q.",NA(),INDEX(Data!$B$4:$L$947,MATCH(Graphs!$CK8,Data!$A$4:$A$947,0),MATCH(Graphs!CM$4,Data!$B$3:$L$3,0)))} -> 227.17 | CN8: {=IF(INDEX(Data!$B$4:$L$947,MATCH(Graphs!$CK8,Data!$A$4:$A$947,0),MATCH(Graphs!CN$4,Data!$B$3:$L$3,0))="n.q.",NA(),INDEX(Data!$B$4:$L$947,MATCH(Graphs!$CK8,Data!$A$4:$A$947,0),MATCH(Graphs!CN$4,Data!$B$3:$L$3,0)))} -> 219 | CO8: {=IF(INDEX(Data!$B$4:$L$947,MATCH(Graphs!$CK8,Data!$A$4:$A$947,0),MATCH(Graphs!CO$4,Data!$B$3:$L$3,0))="n.q.",NA(),INDEX(Data!$B$4:$L$947,MATCH(Graphs!$CK8,Data!$A$4:$A$947,0),MATCH(Graphs!CO$4,Data!$B$3:$L$3,0)))} -> #N/A | CP8: {=IF(INDEX(Data!$B$4:$L$947,MATCH(Graphs!$CK8,Data!$A$4:$A$947,0),MATCH(Graphs!CP$4,Data!$B$3:$L$3,0))="n.q.",NA(),INDEX(Data!$B$4:$L$947,MATCH(Graphs!$CK8,Data!$A$4:$A$947,0),MATCH(Graphs!CP$4,Data!$B$3:$L$3,0)))} -> #N/A | CR8: {=IF(INDEX(Data!$P$4:$Z$947,MATCH(Graphs!$CK8,Data!$A$4:$A$947,0),MATCH(Graphs!CR$4,Data!$P$3:$Z$3,0))="n.q.",NA(),INDEX(Data!$P$4:$Z$947,MATCH(Graphs!$CK8,Data!$A$4:$A$947,0),MATCH(Graphs!CR$4,Data!$P$3:$Z$3,0)))} -> #N/A | CS8: {=IF(INDEX(Data!$P$4:$Z$947,MATCH(Graphs!$CK8,Data!$A$4:$A$947,0),MATCH(Graphs!CS$4,Data!$P$3:$Z$3,0))="n.q.",NA(),INDEX(Data!$P$4:$Z$947,MATCH(Graphs!$CK8,Data!$A$4:$A$947,0),MATCH(Graphs!CS$4,Data!$P$3:$Z$3,0)))} -> #N/A | CT8: {=IF(INDEX(Data!$P$4:$Z$947,MATCH(Graphs!$CK8,Data!$A$4:$A$947,0),MATCH(Graphs!CT$4,Data!$P$3:$Z$3,0))="n.q.",NA(),INDEX(Data!$P$4:$Z$947,MATCH(Graphs!$CK8,Data!$A$4:$A$947,0),MATCH(Graphs!CT$4,Data!$P$3:$Z$3,0)))} -> #N/A | CU8: {=IF(INDEX(Data!$P$4:$Z$947,MATCH(Graphs!$CK8,Data!$A$4:$A$947,0),MATCH(Graphs!CU$4,Data!$P$3:$Z$3,0))="n.q.",NA(),INDEX(Data!$P$4:$Z$947,MATCH(Graphs!$CK8,Data!$A$4:$A$947,0),MATCH(Graphs!CU$4,Data!$P$3:$Z$3,0)))} -> #N/A | CV8: {=IF(INDEX(Data!$P$4:$Z$947,MATCH(Graphs!$CK8,Data!$A$4:$A$947,0),MATCH(Graphs!CV$4,Data!$P$3:$Z$3,0))="n.q.",NA(),INDEX(Data!$P$4:$Z$947,MATCH(Graphs!$CK8,Data!$A$4:$A$947,0),MATCH(Graphs!CV$4,Data!$P$3:$Z$3,0)))} -> #N/A
CK9: =Data!A8 -> 45938 | CL9: {=IF(INDEX(Data!$B$4:$L$947,MATCH(Graphs!$CK9,Data!$A$4:$A$947,0),MATCH(Graphs!CL$4,Data!$B$3:$L$3,0))="n.q.",NA(),INDEX(Data!$B$4:$L$947,MATCH(Graphs!$CK9,Data!$A$4:$A$947,0),MATCH(Graphs!CL$4,Data!$B$3:$L$3,0)))} -> 224.68 | CM9: {=IF(INDEX(Data!$B$4:$L$947,MATCH(Graphs!$CK9,Data!$A$4:$A$947,0),MATCH(Graphs!CM$4,Data!$B$3:$L$3,0))="n.q.",NA(),INDEX(Data!$B$4:$L$947,MATCH(Graphs!$CK9,Data!$A$4:$A$947,0),MATCH(Graphs!CM$4,Data!$B$3:$L$3,0)))} -> 229.01 | CN9: {=IF(INDEX(Data!$B$4:$L$947,MATCH(Graphs!$CK9,Data!$A$4:$A$947,0),MATCH(Graphs!CN$4,Data!$B$3:$L$3,0))="n.q.",NA(),INDEX(Data!$B$4:$L$947,MATCH(Graphs!$CK9,Data!$A$4:$A$947,0),MATCH(Graphs!CN$4,Data!$B$3:$L$3,0)))} -> 217 | CO9: {=IF(INDEX(Data!$B$4:$L$947,MATCH(Graphs!$CK9,Data!$A$4:$A$947,0),MATCH(Graphs!CO$4,Data!$B$3:$L$3,0))="n.q.",NA(),INDEX(Data!$B$4:$L$947,MATCH(Graphs!$CK9,Data!$A$4:$A$947,0),MATCH(Graphs!CO$4,Data!$B$3:$L$3,0)))} -> #N/A | CP9: {=IF(INDEX(Data!$B$4:$L$947,MATCH(Graphs!$CK9,Data!$A$4:$A$947,0),MATCH(Graphs!CP$4,Data!$B$3:$L$3,0))="n.q.",NA(),INDEX(Data!$B$4:$L$947,MATCH(Graphs!$CK9,Data!$A$4:$A$947,0),MATCH(Graphs!CP$4,Data!$B$3:$L$3,0)))} -> #N/A | CR9: {=IF(INDEX(Data!$P$4:$Z$947,MATCH(Graphs!$CK9,Data!$A$4:$A$947,0),MATCH(Graphs!CR$4,Data!$P$3:$Z$3,0))="n.q.",NA(),INDEX(Data!$P$4:$Z$947,MATCH(Graphs!$CK9,Data!$A$4:$A$947,0),MATCH(Graphs!CR$4,Data!$P$3:$Z$3,0)))} -> 173.69915 | CS9: {=IF(INDEX(Data!$P$4:$Z$947,MATCH(Graphs!$CK9,Data!$A$4:$A$947,0),MATCH(Graphs!CS$4,Data!$P$3:$Z$3,0))="n.q.",NA(),INDEX(Data!$P$4:$Z$947,MATCH(Graphs!$CK9,Data!$A$4:$A$947,0),MATCH(Graphs!CS$4,Data!$P$3:$Z$3,0)))} -> #N/A | CT9: {=IF(INDEX(Data!$P$4:$Z$947,MATCH(Graphs!$CK9,Data!$A$4:$A$947,0),MATCH(Graphs!CT$4,Data!$P$3:$Z$3,0))="n.q.",NA(),INDEX(Data!$P$4:$Z$947,MATCH(Graphs!$CK9,Data!$A$4:$A$947,0),MATCH(Graphs!CT$4,Data!$P$3:$Z$3,0)))} -> 184.05436 | CU9: {=IF(INDEX(Data!$P$4:$Z$947,MATCH(Graphs!$CK9,Data!$A$4:$A$947,0),MATCH(Graphs!CU$4,Data!$P$3:$Z$3,0))="n.q.",NA(),INDEX(Data!$P$4:$Z$947,MATCH(Graphs!$CK9,Data!$A$4:$A$947,0),MATCH(Graphs!CU$4,Data!$P$3:$Z$3,0)))} -> #N/A | CV9: {=IF(INDEX(Data!$P$4:$Z$947,MATCH(Graphs!$CK9,Data!$A$4:$A$947,0),MATCH(Graphs!CV$4,Data!$P$3:$Z$3,0))="n.q.",NA(),INDEX(Data!$P$4:$Z$947,MATCH(Graphs!$CK9,Data!$A$4:$A$947,0),MATCH(Graphs!CV$4,Data!$P$3:$Z$3,0)))} -> #N/A
CK10: =Data!A9 -> 45931 | CL10: {=IF(INDEX(Data!$B$4:$L$947,MATCH(Graphs!$CK10,Data!$A$4:$A$947,0),MATCH(Graphs!CL$4,Data!$B$3:$L$3,0))="n.q.",NA(),INDEX(Data!$B$4:$L$947,MATCH(Graphs!$CK10,Data!$A$4:$A$947,0),MATCH(Graphs!CL$4,Data!$B$3:$L$3,0)))} -> 225.77 | CM10: {=IF(INDEX(Data!$B$4:$L$947,MATCH(Graphs!$CK10,Data!$A$4:$A$947,0),MATCH(Graphs!CM$4,Data!$B$3:$L$3,0))="n.q.",NA(),INDEX(Data!$B$4:$L$947,MATCH(Graphs!$CK10,Data!$A$4:$A$947,0),MATCH(Graphs!CM$4,Data!$B$3:$L$3,0)))} -> 227.99 | CN10: {=IF(INDEX(Data!$B$4:$L$947,MATCH(Graphs!$CK10,Data!$A$4:$A$947,0),MATCH(Graphs!CN$4,Data!$B$3:$L$3,0))="n.q.",NA(),INDEX(Data!$B$4:$L$947,MATCH(Graphs!$CK10,Data!$A$4:$A$947,0),MATCH(Graphs!CN$4,Data!$B$3:$L$3,0)))} -> 216 | CO10: {=IF(INDEX(Data!$B$4:$L$947,MATCH(Graphs!$CK10,Data!$A$4:$A$947,0),MATCH(Graphs!CO$4,Data!$B$3:$L$3,0))="n.q.",NA(),INDEX(Data!$B$4:$L$947,MATCH(Graphs!$CK10,Data!$A$4:$A$947,0),MATCH(Graphs!CO$4,Data!$B$3:$L$3,0)))} -> #N/A | CP10: {=IF(INDEX(Data!$B$4:$L$947,MATCH(Graphs!$CK10,Data!$A$4:$A$947,0),MATCH(Graphs!CP$4,Data!$B$3:$L$3,0))="n.q.",NA(),INDEX(Data!$B$4:$L$947,MATCH(Graphs!$CK10,Data!$A$4:$A$947,0),MATCH(Graphs!CP$4,Data!$B$3:$L$3,0)))} -> #N/A | CR10: {=IF(INDEX(Data!$P$4:$Z$947,MATCH(Graphs!$CK10,Data!$A$4:$A$947,0),MATCH(Graphs!CR$4,Data!$P$3:$Z$3,0))="n.q.",NA(),INDEX(Data!$P$4:$Z$947,MATCH(Graphs!$CK10,Data!$A$4:$A$947,0),MATCH(Graphs!CR$4,Data!$P$3:$Z$3,0)))} -> 171.4176 | CS10: {=IF(INDEX(Data!$P$4:$Z$947,MATCH(Graphs!$CK10,Data!$A$4:$A$947,0),MATCH(Graphs!CS$4,Data!$P$3:$Z$3,0))="n.q.",NA(),INDEX(Data!$P$4:$Z$947,MATCH(Graphs!$CK10,Data!$A$4:$A$947,0),MATCH(Graphs!CS$4,Data!$P$3:$Z$3,0)))} -> #N/A | CT10: {=IF(INDEX(Data!$P$4:$Z$947,MATCH(Graphs!$CK10,Data!$A$4:$A$947,0),MATCH(Graphs!CT$4,Data!$P$3:$Z$3,0))="n.q.",NA(),INDEX(Data!$P$4:$Z$947,MATCH(Graphs!$CK10,Data!$A$4:$A$947,0),MATCH(Graphs!CT$4,Data!$P$3:$Z$3,0)))} -> 182.53156 | CU10: {=IF(INDEX(Data!$P$4:$Z$947,MATCH(Graphs!$CK10,Data!$A$4:$A$947,0),MATCH(Graphs!CU$4,Data!$P$3:$Z$3,0))="n.q.",NA(),INDEX(Data!$P$4:$Z$947,MATCH(Graphs!$CK10,Data!$A$4:$A$947,0),MATCH(Graphs!CU$4,Data!$P$3:$Z$3,0)))} -> #N/A | CV10: {=IF(INDEX(Data!$P$4:$Z$947,MATCH(Graphs!$CK10,Data!$A$4:$A$947,0),MATCH(Graphs!CV$4,Data!$P$3:$Z$3,0))="n.q.",NA(),INDEX(Data!$P$4:$Z$947,MATCH(Graphs!$CK10,Data!$A$4:$A$947,0),MATCH(Graphs!CV$4,Data!$P$3:$Z$3,0)))} -> #N/A
CK11: =Data!A10 -> 45924 | CL11: {=IF(INDEX(Data!$B$4:$L$947,MATCH(Graphs!$CK11,Data!$A$4:$A$947,0),MATCH(Graphs!CL$4,Data!$B$3:$L$3,0))="n.q.",NA(),INDEX(Data!$B$4:$L$947,MATCH(Graphs!$CK11,Data!$A$4:$A$947,0),MATCH(Graphs!CL$4,Data!$B$3:$L$3,0)))} -> 229.72 | CM11: {=IF(INDEX(Data!$B$4:$L$947,MATCH(Graphs!$CK11,Data!$A$4:$A$947,0),MATCH(Graphs!CM$4,Data!$B$3:$L$3,0))="n.q.",NA(),INDEX(Data!$B$4:$L$947,MATCH(Graphs!$CK11,Data!$A$4:$A$947,0),MATCH(Graphs!CM$4,Data!$B$3:$L$3,0)))} -> 233.97 | CN11: {=IF(INDEX(Data!$B$4:$L$947,MATCH(Graphs!$CK11,Data!$A$4:$A$947,0),MATCH(Graphs!CN$4,Data!$B$3:$L$3,0))="n.q.",NA(),INDEX(Data!$B$4:$L$947,MATCH(Graphs!$CK11,Data!$A$4:$A$947,0),MATCH(Graphs!CN$4,Data!$B$3:$L$3,0)))} -> 216 | CO11: {=IF(INDEX(Data!$B$4:$L$947,MATCH(Graphs!$CK11,Data!$A$4:$A$947,0),MATCH(Graphs!CO$4,Data!$B$3:$L$3,0))="n.q.",NA(),INDEX(Data!$B$4:$L$947,MATCH(Graphs!$CK11,Data!$A$4:$A$947,0),MATCH(Graphs!CO$4,Data!$B$3:$L$3,0)))} -> #N/A | CP11: {=IF(INDEX(Data!$B$4:$L$947,MATCH(Graphs!$CK11,Data!$A$4:$A$947,0),MATCH(Graphs!CP$4,Data!$B$3:$L$3,0))="n.q.",NA(),INDEX(Data!$B$4:$L$947,MATCH(Graphs!$CK11,Data!$A$4:$A$947,0),MATCH(Graphs!CP$4,Data!$B$3:$L$3,0)))} -> #N/A | CR11: {=IF(INDEX(Data!$P$4:$Z$947,MATCH(Graphs!$CK11,Data!$A$4:$A$947,0),MATCH(Graphs!CR$4,Data!$P$3:$Z$3,0))="n.q.",NA(),INDEX(Data!$P$4:$Z$947,MATCH(Graphs!$CK11,Data!$A$4:$A$947,0),MATCH(Graphs!CR$4,Data!$P$3:$Z$3,0)))} -> 174.21742 | CS11: {=IF(INDEX(Data!$P$4:$Z$947,MATCH(Graphs!$CK11,Data!$A$4:$A$947,0),MATCH(Graphs!CS$4,Data!$P$3:$Z$3,0))="n.q.",NA(),INDEX(Data!$P$4:$Z$947,MATCH(Graphs!$CK11,Data!$A$4:$A$947,0),MATCH(Graphs!CS$4,Data!$P$3:$Z$3,0)))} -> #N/A | CT11: {=IF(INDEX(Data!$P$4:$Z$947,MATCH(Graphs!$CK11,Data!$A$4:$A$947,0),MATCH(Graphs!CT$4,Data!$P$3:$Z$3,0))="n.q.",NA(),INDEX(Data!$P$4:$Z$947,MATCH(Graphs!$CK11,Data!$A$4:$A$947,0),MATCH(Graphs!CT$4,Data!$P$3:$Z$3,0)))} -> 187.13848 | CU11: {=IF(INDEX(Data!$P$4:$Z$947,MATCH(Graphs!$CK11,Data!$A$4:$A$947,0),MATCH(Graphs!CU$4,Data!$P$3:$Z$3,0))="n.q.",NA(),INDEX(Data!$P$4:$Z$947,MATCH(Graphs!$CK11,Data!$A$4:$A$947,0),MATCH(Graphs!CU$4,Data!$P$3:$Z$3,0)))} -> #N/A | CV11: {=IF(INDEX(Data!$P$4:$Z$947,MATCH(Graphs!$CK11,Data!$A$4:$A$947,0),MATCH(Graphs!CV$4,Data!$P$3:$Z$3,0))="n.q.",NA(),INDEX(Data!$P$4:$Z$947,MATCH(Graphs!$CK11,Data!$A$4:$A$947,0),MATCH(Graphs!CV$4,Data!$P$3:$Z$3,0)))} -> #N/A
CK12: =Data!A11 -> 45917 | CL12: {=IF(INDEX(Data!$B$4:$L$947,MATCH(Graphs!$CK12,Data!$A$4:$A$947,0),MATCH(Graphs!CL$4,Data!$B$3:$L$3,0))="n.q.",NA(),INDEX(Data!$B$4:$L$947,MATCH(Graphs!$CK12,Data!$A$4:$A$947,0),MATCH(Graphs!CL$4,Data!$B$3:$L$3,0)))} -> 232.33 | CM12: {=IF(INDEX(Data!$B$4:$L$947,MATCH(Graphs!$CK12,Data!$A$4:$A$947,0),MATCH(Graphs!CM$4,Data!$B$3:$L$3,0))="n.q.",NA(),INDEX(Data!$B$4:$L$947,MATCH(Graphs!$CK12,Data!$A$4:$A$947,0),MATCH(Graphs!CM$4,Data!$B$3:$L$3,0)))} -> 237.46 | CN12: {=IF(INDEX(Data!$B$4:$L$947,MATCH(Graphs!$CK12,Data!$A$4:$A$947,0),MATCH(Graphs!CN$4,Data!$B$3:$L$3,0))="n.q.",NA(),INDEX(Data!$B$4:$L$947,MATCH(Graphs!$CK12,Data!$A$4:$A$947,0),MATCH(Graphs!CN$4,Data!$B$3:$L$3,0)))} -> 217 | CO12: {=IF(INDEX(Data!$B$4:$L$947,MATCH(Graphs!$CK12,Data!$A$4:$A$947,0),MATCH(Graphs!CO$4,Data!$B$3:$L$3,0))="n.q.",NA(),INDEX(Data!$B$4:$L$947,MATCH(Graphs!$CK12,Data!$A$4:$A$947,0),MATCH(Graphs!CO$4,Data!$B$3:$L$3,0)))} -> #N/A | CP12: {=IF(INDEX(Data!$B$4:$L$947,MATCH(Graphs!$CK12,Data!$A$4:$A$947,0),MATCH(Graphs!CP$4,Data!$B$3:$L$3,0))="n.q.",NA(),INDEX(Data!$B$4:$L$947,MATCH(Graphs!$CK12,Data!$A$4:$A$947,0),MATCH(Graphs!CP$4,Data!$B$3:$L$3,0)))} -> #N/A | CR12: {=IF(INDEX(Data!$P$4:$Z$947,MATCH(Graphs!$CK12,Data!$A$4:$A$947,0),MATCH(Graphs!CR$4,Data!$P$3:$Z$3,0))="n.q.",NA(),INDEX(Data!$P$4:$Z$947,MATCH(Graphs!$CK12,Data!$A$4:$A$947,0),MATCH(Graphs!CR$4,Data!$P$3:$Z$3,0)))} -> 175.18797 | CS12: {=IF(INDEX(Data!$P$4:$Z$947,MATCH(Graphs!$CK12,Data!$A$4:$A$947,0),MATCH(Graphs!CS$4,Data!$P$3:$Z$3,0))="n.q.",NA(),INDEX(Data!$P$4:$Z$947,MATCH(Graphs!$CK12,Data!$A$4:$A$947,0),MATCH(Graphs!CS$4,Data!$P$3:$Z$3,0)))} -> #N/A | CT12: {=IF(INDEX(Data!$P$4:$Z$947,MATCH(Graphs!$CK12,Data!$A$4:$A$947,0),MATCH(Graphs!CT$4,Data!$P$3:$Z$3,0))="n.q.",NA(),INDEX(Data!$P$4:$Z$947,MATCH(Graphs!$CK12,Data!$A$4:$A$947,0),MATCH(Graphs!CT$4,Data!$P$3:$Z$3,0)))} -> 184.16829 | CU12: {=IF(INDEX(Data!$P$4:$Z$947,MATCH(Graphs!$CK12,Data!$A$4:$A$947,0),MATCH(Graphs!CU$4,Data!$P$3:$Z$3,0))="n.q.",NA(),INDEX(Data!$P$4:$Z$947,MATCH(Graphs!$CK12,Data!$A$4:$A$947,0),MATCH(Graphs!CU$4,Data!$P$3:$Z$3,0)))} -> #N/A | CV12: {=IF(INDEX(Data!$P$4:$Z$947,MATCH(Graphs!$CK12,Data!$A$4:$A$947,0),MATCH(Graphs!CV$4,Data!$P$3:$Z$3,0))="n.q.",NA(),INDEX(Data!$P$4:$Z$947,MATCH(Graphs!$CK12,Data!$A$4:$A$947,0),MATCH(Graphs!CV$4,Data!$P$3:$Z$3,0)))} -> #N/A
CK13: =Data!A12 -> 45910 | CL13: {=IF(INDEX(Data!$B$4:$L$947,MATCH(Graphs!$CK13,Data!$A$4:$A$947,0),MATCH(Graphs!CL$4,Data!$B$3:$L$3,0))="n.q.",NA(),INDEX(Data!$B$4:$L$947,MATCH(Graphs!$CK13,Data!$A$4:$A$947,0),MATCH(Graphs!CL$4,Data!$B$3:$L$3,0)))} -> 224.51 | CM13: {=IF(INDEX(Data!$B$4:$L$947,MATCH(Graphs!$CK13,Data!$A$4:$A$947,0),MATCH(Graphs!CM$4,Data!$B$3:$L$3,0))="n.q.",NA(),INDEX(Data!$B$4:$L$947,MATCH(Graphs!$CK13,Data!$A$4:$A$947,0),MATCH(Graphs!CM$4,Data!$B$3:$L$3,0)))} -> 234.06 | CN13: {=IF(INDEX(Data!$B$4:$L$947,MATCH(Graphs!$CK13,Data!$A$4:$A$947,0),MATCH(Graphs!CN$4,Data!$B$3:$L$3,0))="n.q.",NA(),INDEX(Data!$B$4:$L$947,MATCH(Graphs!$CK13,Data!$A$4:$A$947,0),MATCH(Graphs!CN$4,Data!$B$3:$L$3,0)))} -> 215 | CO13: {=IF(INDEX(Data!$B$4:$L$947,MATCH(Graphs!$CK13,Data!$A$4:$A$947,0),MATCH(Graphs!CO$4,Data!$B$3:$L$3,0))="n.q.",NA(),INDEX(Data!$B$4:$L$947,MATCH(Graphs!$CK13,Data!$A$4:$A$947,0),MATCH(Graphs!CO$4,Data!$B$3:$L$3,0)))} -> #N/A | CP13: {=IF(INDEX(Data!$B$4:$L$947,MATCH(Graphs!$CK13,Data!$A$4:$A$947,0),MATCH(Graphs!CP$4,Data!$B$3:$L$3,0))="n.q.",NA(),INDEX(Data!$B$4:$L$947,MATCH(Graphs!$CK13,Data!$A$4:$A$947,0),MATCH(Graphs!CP$4,Data!$B$3:$L$3,0)))} -> #N/A | CR13: {=IF(INDEX(Data!$P$4:$Z$947,MATCH(Graphs!$CK13,Data!$A$4:$A$947,0),MATCH(Graphs!CR$4,Data!$P$3:$Z$3,0))="n.q.",NA(),INDEX(Data!$P$4:$Z$947,MATCH(Graphs!$CK13,Data!$A$4:$A$947,0),MATCH(Graphs!CR$4,Data!$P$3:$Z$3,0)))} -> 172.84531 | CS13: {=IF(INDEX(Data!$P$4:$Z$947,MATCH(Graphs!$CK13,Data!$A$4:$A$947,0),MATCH(Graphs!CS$4,Data!$P$3:$Z$3,0))="n.q.",NA(),INDEX(Data!$P$4:$Z$947,MATCH(Graphs!$CK13,Data!$A$4:$A$947,0),MATCH(Graphs!CS$4,Data!$P$3:$Z$3,0)))} -> #N/A | CT13: {=IF(INDEX(Data!$P$4:$Z$947,MATCH(Graphs!$CK13,Data!$A$4:$A$947,0),MATCH(Graphs!CT$4,Data!$P$3:$Z$3,0))="n.q.",NA(),INDEX(Data!$P$4:$Z$947,MATCH(Graphs!$CK13,Data!$A$4:$A$947,0),MATCH(Graphs!CT$4,Data!$P$3:$Z$3,0)))} -> 184.505 | CU13: {=IF(INDEX(Data!$P$4:$Z$947,MATCH(Graphs!$CK13,Data!$A$4:$A$947,0),MATCH(Graphs!CU$4,Data!$P$3:$Z$3,0))="n.q.",NA(),INDEX(Data!$P$4:$Z$947,MATCH(Graphs!$CK13,Data!$A$4:$A$947,0),MATCH(Graphs!CU$4,Data!$P$3:$Z$3,0)))} -> #N/A | CV13: {=IF(INDEX(Data!$P$4:$Z$947,MATCH(Graphs!$CK13,Data!$A$4:$A$947,0),MATCH(Graphs!CV$4,Data!$P$3:$Z$3,0))="n.q.",NA(),INDEX(Data!$P$4:$Z$947,MATCH(Graphs!$CK13,Data!$A$4:$A$947,0),MATCH(Graphs!CV$4,Data!$P$3:$Z$3,0)))} -> #N/A
CK14: =Data!A13 -> 45903 | CL14: {=IF(INDEX(Data!$B$4:$L$947,MATCH(Graphs!$CK14,Data!$A$4:$A$947,0),MATCH(Graphs!CL$4,Data!$B$3:$L$3,0))="n.q.",NA(),INDEX(Data!$B$4:$L$947,MATCH(Graphs!$CK14,Data!$A$4:$A$947,0),MATCH(Graphs!CL$4,Data!$B$3:$L$3,0)))} -> 224.93 | CM14: {=IF(INDEX(Data!$B$4:$L$947,MATCH(Graphs!$CK14,Data!$A$4:$A$947,0),MATCH(Graphs!CM$4,Data!$B$3:$L$3,0))="n.q.",NA(),INDEX(Data!$B$4:$L$947,MATCH(Graphs!$CK14,Data!$A$4:$A$947,0),MATCH(Graphs!CM$4,Data!$B$3:$L$3,0)))} -> 226.98 | CN14: {=IF(INDEX(Data!$B$4:$L$947,MATCH(Graphs!$CK14,Data!$A$4:$A$947,0),MATCH(Graphs!CN$4,Data!$B$3:$L$3,0))="n.q.",NA(),INDEX(Data!$B$4:$L$947,MATCH(Graphs!$CK14,Data!$A$4:$A$947,0),MATCH(Graphs!CN$4,Data!$B$3:$L$3,0)))} -> 211 | CO14: {=IF(INDEX(Data!$B$4:$L$947,MATCH(Graphs!$CK14,Data!$A$4:$A$947,0),MATCH(Graphs!CO$4,Data!$B$3:$L$3,0))="n.q.",NA(),INDEX(Data!$B$4:$L$947,MATCH(Graphs!$CK14,Data!$A$4:$A$947,0),MATCH(Graphs!CO$4,Data!$B$3:$L$3,0)))} -> #N/A | CP14: {=IF(INDEX(Data!$B$4:$L$947,MATCH(Graphs!$CK14,Data!$A$4:$A$947,0),MATCH(Graphs!CP$4,Data!$B$3:$L$3,0))="n.q.",NA(),INDEX(Data!$B$4:$L$947,MATCH(Graphs!$CK14,Data!$A$4:$A$947,0),MATCH(Graphs!CP$4,Data!$B$3:$L$3,0)))} -> #N/A | CR14: {=IF(INDEX(Data!$P$4:$Z$947,MATCH(Graphs!$CK14,Data!$A$4:$A$947,0),MATCH(Graphs!CR$4,Data!$P$3:$Z$3,0))="n.q.",NA(),INDEX(Data!$P$4:$Z$947,MATCH(Graphs!$CK14,Data!$A$4:$A$947,0),MATCH(Graphs!CR$4,Data!$P$3:$Z$3,0)))} -> 178.03999 | CS14: {=IF(INDEX(Data!$P$4:$Z$947,MATCH(Graphs!$CK14,Data!$A$4:$A$947,0),MATCH(Graphs!CS$4,Data!$P$3:$Z$3,0))="n.q.",NA(),INDEX(Data!$P$4:$Z$947,MATCH(Graphs!$CK14,Data!$A$4:$A$947,0),MATCH(Graphs!CS$4,Data!$P$3:$Z$3,0)))} -> #N/A | CT14: {=IF(INDEX(Data!$P$4:$Z$947,MATCH(Graphs!$CK14,Data!$A$4:$A$947,0),MATCH(Graphs!CT$4,Data!$P$3:$Z$3,0))="n.q.",NA(),INDEX(Data!$P$4:$Z$947,MATCH(Graphs!$CK14,Data!$A$4:$A$947,0),MATCH(Graphs!CT$4,Data!$P$3:$Z$3,0)))} -> 197.37407 | CU14: {=IF(INDEX(Data!$P$4:$Z$947,MATCH(Graphs!$CK14,Data!$A$4:$A$947,0),MATCH(Graphs!CU$4,Data!$P$3:$Z$3,0))="n.q.",NA(),INDEX(Data!$P$4:$Z$947,MATCH(Graphs!$CK14,Data!$A$4:$A$947,0),MATCH(Graphs!CU$4,Data!$P$3:$Z$3,0)))} -> #N/A | CV14: {=IF(INDEX(Data!$P$4:$Z$947,MATCH(Graphs!$CK14,Data!$A$4:$A$947,0),MATCH(Graphs!CV$4,Data!$P$3:$Z$3,0))="n.q.",NA(),INDEX(Data!$P$4:$Z$947,MATCH(Graphs!$CK14,Data!$A$4:$A$947,0),MATCH(Graphs!CV$4,Data!$P$3:$Z$3,0)))} -> #N/A
CK15: =Data!A14 -> 45896 | CL15: {=IF(INDEX(Data!$B$4:$L$947,MATCH(Graphs!$CK15,Data!$A$4:$A$947,0),MATCH(Graphs!CL$4,Data!$B$3:$L$3,0))="n.q.",NA(),INDEX(Data!$B$4:$L$947,MATCH(Graphs!$CK15,Data!$A$4:$A$947,0),MATCH(Graphs!CL$4,Data!$B$3:$L$3,0)))} -> 230.15 | CM15: {=IF(INDEX(Data!$B$4:$L$947,MATCH(Graphs!$CK15,Data!$A$4:$A$947,0),MATCH(Graphs!CM$4,Data!$B$3:$L$3,0))="n.q.",NA(),INDEX(Data!$B$4:$L$947,MATCH(Graphs!$CK15,Data!$A$4:$A$947,0),MATCH(Graphs!CM$4,Data!$B$3:$L$3,0)))} -> 226.16 | CN15: {=IF(INDEX(Data!$B$4:$L$947,MATCH(Graphs!$CK15,Data!$A$4:$A$947,0),MATCH(Graphs!CN$4,Data!$B$3:$L$3,0))="n.q.",NA(),INDEX(Data!$B$4:$L$947,MATCH(Graphs!$CK15,Data!$A$4:$A$947,0),MATCH(Graphs!CN$4,Data!$B$3:$L$3,0)))} -> 213 | CO15: {=IF(INDEX(Data!$B$4:$L$947,MATCH(Graphs!$CK15,Data!$A$4:$A$947,0),MATCH(Graphs!CO$4,Data!$B$3:$L$3,0))="n.q.",NA(),INDEX(Data!$B$4:$L$947,MATCH(Graphs!$CK15,Data!$A$4:$A$947,0),MATCH(Graphs!CO$4,Data!$B$3:$L$3,0)))} -> #N/A | CP15: {=IF(INDEX(Data!$B$4:$L$947,MATCH(Graphs!$CK15,Data!$A$4:$A$947,0),MATCH(Graphs!CP$4,Data!$B$3:$L$3,0))="n.q.",NA(),INDEX(Data!$B$4:$L$947,MATCH(Graphs!$CK15,Data!$A$4:$A$947,0),MATCH(Graphs!CP$4,Data!$B$3:$L$3,0)))} -> #N/A | CR15: {=IF(INDEX(Data!$P$4:$Z$947,MATCH(Graphs!$CK15,Data!$A$4:$A$947,0),MATCH(Graphs!CR$4,Data!$P$3:$Z$3,0))="n.q.",NA(),INDEX(Data!$P$4:$Z$947,MATCH(Graphs!$CK15,Data!$A$4:$A$947,0),MATCH(Graphs!CR$4,Data!$P$3:$Z$3,0)))} -> 174.38109 | CS15: {=IF(INDEX(Data!$P$4:$Z$947,MATCH(Graphs!$CK15,Data!$A$4:$A$947,0),MATCH(Graphs!CS$4,Data!$P$3:$Z$3,0))="n.q.",NA(),INDEX(Data!$P$4:$Z$947,MATCH(Graphs!$CK15,Data!$A$4:$A$947,0),MATCH(Graphs!CS$4,Data!$P$3:$Z$3,0)))} -> #N/A | CT15: {=IF(INDEX(Data!$P$4:$Z$947,MATCH(Graphs!$CK15,Data!$A$4:$A$947,0),MATCH(Graphs!CT$4,Data!$P$3:$Z$3,0))="n.q.",NA(),INDEX(Data!$P$4:$Z$947,MATCH(Graphs!$CK15,Data!$A$4:$A$947,0),MATCH(Graphs!CT$4,Data!$P$3:$Z$3,0)))} -> 209.60925 | CU15: {=IF(INDEX(Data!$P$4:$Z$947,MATCH(Graphs!$CK15,Data!$A$4:$A$947,0),MATCH(Graphs!CU$4,Data!$P$3:$Z$3,0))="n.q.",NA(),INDEX(Data!$P$4:$Z$947,MATCH(Graphs!$CK15,Data!$A$4:$A$947,0),MATCH(Graphs!CU$4,Data!$P$3:$Z$3,0)))} -> #N/A | CV15: {=IF(INDEX(Data!$P$4:$Z$947,MATCH(Graphs!$CK15,Data!$A$4:$A$947,0),MATCH(Graphs!CV$4,Data!$P$3:$Z$3,0))="n.q.",NA(),INDEX(Data!$P$4:$Z$947,MATCH(Graphs!$CK15,Data!$A$4:$A$947,0),MATCH(Graphs!CV$4,Data!$P$3:$Z$3,0)))} -> #N/A
CK16: =Data!A15 -> 45889 | CL16: {=IF(INDEX(Data!$B$4:$L$947,MATCH(Graphs!$CK16,Data!$A$4:$A$947,0),MATCH(Graphs!CL$4,Data!$B$3:$L$3,0))="n.q.",NA(),INDEX(Data!$B$4:$L$947,MATCH(Graphs!$CK16,Data!$A$4:$A$947,0),MATCH(Graphs!CL$4,Data!$B$3:$L$3,0)))} -> 232.63 | CM16: {=IF(INDEX(Data!$B$4:$L$947,MATCH(Graphs!$CK16,Data!$A$4:$A$947,0),MATCH(Graphs!CM$4,Data!$B$3:$L$3,0))="n.q.",NA(),INDEX(Data!$B$4:$L$947,MATCH(Graphs!$CK16,Data!$A$4:$A$947,0),MATCH(Graphs!CM$4,Data!$B$3:$L$3,0)))} -> 231.76 | CN16: {=IF(INDEX(Data!$B$4:$L$947,MATCH(Graphs!$CK16,Data!$A$4:$A$947,0),MATCH(Graphs!CN$4,Data!$B$3:$L$3,0))="n.q.",NA(),INDEX(Data!$B$4:$L$947,MATCH(Graphs!$CK16,Data!$A$4:$A$947,0),MATCH(Graphs!CN$4,Data!$B$3:$L$3,0)))} -> 215 | CO16: {=IF(INDEX(Data!$B$4:$L$947,MATCH(Graphs!$CK16,Data!$A$4:$A$947,0),MATCH(Graphs!CO$4,Data!$B$3:$L$3,0))="n.q.",NA(),INDEX(Data!$B$4:$L$947,MATCH(Graphs!$CK16,Data!$A$4:$A$947,0),MATCH(Graphs!CO$4,Data!$B$3:$L$3,0)))} -> #N/A | CP16: {=IF(INDEX(Data!$B$4:$L$947,MATCH(Graphs!$CK16,Data!$A$4:$A$947,0),MATCH(Graphs!CP$4,Data!$B$3:$L$3,0))="n.q.",NA(),INDEX(Data!$B$4:$L$947,MATCH(Graphs!$CK16,Data!$A$4:$A$947,0),MATCH(Graphs!CP$4,Data!$B$3:$L$3,0)))} -> #N/A | CR16: {=IF(INDEX(Data!$P$4:$Z$947,MATCH(Graphs!$CK16,Data!$A$4:$A$947,0),MATCH(Graphs!CR$4,Data!$P$3:$Z$3,0))="n.q.",NA(),INDEX(Data!$P$4:$Z$947,MATCH(Graphs!$CK16,Data!$A$4:$A$947,0),MATCH(Graphs!CR$4,Data!$P$3:$Z$3,0)))} -> 172.66329 | CS16: {=IF(INDEX(Data!$P$4:$Z$947,MATCH(Graphs!$CK16,Data!$A$4:$A$947,0),MATCH(Graphs!CS$4,Data!$P$3:$Z$3,0))="n.q.",NA(),INDEX(Data!$P$4:$Z$947,MATCH(Graphs!$CK16,Data!$A$4:$A$947,0),MATCH(Graphs!CS$4,Data!$P$3:$Z$3,0)))} -> #N/A | CT16: {=IF(INDEX(Data!$P$4:$Z$947,MATCH(Graphs!$CK16,Data!$A$4:$A$947,0),MATCH(Graphs!CT$4,Data!$P$3:$Z$3,0))="n.q.",NA(),INDEX(Data!$P$4:$Z$947,MATCH(Graphs!$CK16,Data!$A$4:$A$947,0),MATCH(Graphs!CT$4,Data!$P$3:$Z$3,0)))} -> 208.56579 | CU16: {=IF(INDEX(Data!$P$4:$Z$947,MATCH(Graphs!$CK16,Data!$A$4:$A$947,0),MATCH(Graphs!CU$4,Data!$P$3:$Z$3,0))="n.q.",NA(),INDEX(Data!$P$4:$Z$947,MATCH(Graphs!$CK16,Data!$A$4:$A$947,0),MATCH(Graphs!CU$4,Data!$P$3:$Z$3,0)))} -> #N/A | CV16: {=IF(INDEX(Data!$P$4:$Z$947,MATCH(Graphs!$CK16,Data!$A$4:$A$947,0),MATCH(Graphs!CV$4,Data!$P$3:$Z$3,0))="n.q.",NA(),INDEX(Data!$P$4:$Z$947,MATCH(Graphs!$CK16,Data!$A$4:$A$947,0),MATCH(Graphs!CV$4,Data!$P$3:$Z$3,0)))} -> #N/A
... CK26: =Data!A25 -> 45819 | CL26: {=IF(INDEX(Data!$B$4:$L$947,MATCH(Graphs!$CK26,Data!$A$4:$A$947,0),MATCH(Graphs!CL$4,Data!$B$3:$L$3,0))="n.q.",NA(),INDEX(Data!$B$4:$L$947,MATCH(Graphs!$CK26,Data!$A$4:$A$947,0),MATCH(Graphs!CL$4,Data!$B$3:$L$3,0)))} -> 227.52 | CM26: {=IF(INDEX(Data!$B$4:$L$947,MATCH(Graphs!$CK26,Data!$A$4:$A$947,0),MATCH(Graphs!CM$4,Data!$B$3:$L$3,0))="n.q.",NA(),INDEX(Data!$B$4:$L$947,MATCH(Graphs!$CK26,Data!$A$4:$A$947,0),MATCH(Graphs!CM$4,Data!$B$3:$L$3,0)))} -> 235.62 | CN26: {=IF(INDEX(Data!$B$4:$L$947,MATCH(Graphs!$CK26,Data!$A$4:$A$947,0),MATCH(Graphs!CN$4,Data!$B$3:$L$3,0))="n.q.",NA(),INDEX(Data!$B$4:$L$947,MATCH(Graphs!$CK26,Data!$A$4:$A$947,0),MATCH(Graphs!CN$4,Data!$B$3:$L$3,0)))} -> 212 | CO26: {=IF(INDEX(Data!$B$4:$L$947,MATCH(Graphs!$CK26,Data!$A$4:$A$947,0),MATCH(Graphs!CO$4,Data!$B$3:$L$3,0))="n.q.",NA(),INDEX(Data!$B$4:$L$947,MATCH(Graphs!$CK26,Data!$A$4:$A$947,0),MATCH(Graphs!CO$4,Data!$B$3:$L$3,0)))} -> #N/A | CP26: {=IF(INDEX(Data!$B$4:$L$947,MATCH(Graphs!$CK26,Data!$A$4:$A$947,0),MATCH(Graphs!CP$4,Data!$B$3:$L$3,0))="n.q.",NA(),INDEX(Data!$B$4:$L$947,MATCH(Graphs!$CK26,Data!$A$4:$A$947,0),MATCH(Graphs!CP$4,Data!$B$3:$L$3,0)))} -> #N/A | CR26: {=IF(INDEX(Data!$P$4:$Z$947,MATCH(Graphs!$CK26,Data!$A$4:$A$947,0),MATCH(Graphs!CR$4,Data!$P$3:$Z$3,0))="n.q.",NA(),INDEX(Data!$P$4:$Z$947,MATCH(Graphs!$CK26,Data!$A$4:$A$947,0),MATCH(Graphs!CR$4,Data!$P$3:$Z$3,0)))} -> 176.30543 | CS26: {=IF(INDEX(Data!$P$4:$Z$947,MATCH(Graphs!$CK26,Data!$A$4:$A$947,0),MATCH(Graphs!CS$4,Data!$P$3:$Z$3,0))="n.q.",NA(),INDEX(Data!$P$4:$Z$947,MATCH(Graphs!$CK26,Data!$A$4:$A$947,0),MATCH(Graphs!CS$4,Data!$P$3:$Z$3,0)))} -> #N/A | CT26: {=IF(INDEX(Data!$P$4:$Z$947,MATCH(Graphs!$CK26,Data!$A$4:$A$947,0),MATCH(Graphs!CT$4,Data!$P$3:$Z$3,0))="n.q.",NA(),INDEX(Data!$P$4:$Z$947,MATCH(Graphs!$CK26,Data!$A$4:$A$947,0),MATCH(Graphs!CT$4,Data!$P$3:$Z$3,0)))} -> 208.16933 | CU26: {=IF(INDEX(Data!$P$4:$Z$947,MATCH(Graphs!$CK26,Data!$A$4:$A$947,0),MATCH(Graphs!CU$4,Data!$P$3:$Z$3,0))="n.q.",NA(),INDEX(Data!$P$4:$Z$947,MATCH(Graphs!$CK26,Data!$A$4:$A$947,0),MATCH(Graphs!CU$4,Data!$P$3:$Z$3,0)))} -> #N/A | CV26: {=IF(INDEX(Data!$P$4:$Z$947,MATCH(Graphs!$CK26,Data!$A$4:$A$947,0),MATCH(Graphs!CV$4,Data!$P$3:$Z$3,0))="n.q.",NA(),INDEX(Data!$P$4:$Z$947,MATCH(Graphs!$CK26,Data!$A$4:$A$947,0),MATCH(Graphs!CV$4,Data!$P$3:$Z$3,0)))} -> #N/A
C27: Source: International Grains Council, France Agrimer | O27: Source: International Grains Council, France Agrimer | CK27: =Data!A26 -> 45812 | CL27: {=IF(INDEX(Data!$B$4:$L$947,MATCH(Graphs!$CK27,Data!$A$4:$A$947,0),MATCH(Graphs!CL$4,Data!$B$3:$L$3,0))="n.q.",NA(),INDEX(Data!$B$4:$L$947,MATCH(Graphs!$CK27,Data!$A$4:$A$947,0),MATCH(Graphs!CL$4,Data!$B$3:$L$3,0)))} -> 228.49 | CM27: {=IF(INDEX(Data!$B$4:$L$947,MATCH(Graphs!$CK27,Data!$A$4:$A$947,0),MATCH(Graphs!CM$4,Data!$B$3:$L$3,0))="n.q.",NA(),INDEX(Data!$B$4:$L$947,MATCH(Graphs!$CK27,Data!$A$4:$A$947,0),MATCH(Graphs!CM$4,Data!$B$3:$L$3,0)))} -> 240.85 | CN27: {=IF(INDEX(Data!$B$4:$L$947,MATCH(Graphs!$CK27,Data!$A$4:$A$947,0),MATCH(Graphs!CN$4,Data!$B$3:$L$3,0))="n.q.",NA(),INDEX(Data!$B$4:$L$947,MATCH(Graphs!$CK27,Data!$A$4:$A$947,0),MATCH(Graphs!CN$4,Data!$B$3:$L$3,0)))} -> 212 | CO27: {=IF(INDEX(Data!$B$4:$L$947,MATCH(Graphs!$CK27,Data!$A$4:$A$947,0),MATCH(Graphs!CO$4,Data!$B$3:$L$3,0))="n.q.",NA(),INDEX(Data!$B$4:$L$947,MATCH(Graphs!$CK27,Data!$A$4:$A$947,0),MATCH(Graphs!CO$4,Data!$B$3:$L$3,0)))} -> #N/A | CP27: {=IF(INDEX(Data!$B$4:$L$947,MATCH(Graphs!$CK27,Data!$A$4:$A$947,0),MATCH(Graphs!CP$4,Data!$B$3:$L$3,0))="n.q.",NA(),INDEX(Data!$B$4:$L$947,MATCH(Graphs!$CK27,Data!$A$4:$A$947,0),MATCH(Graphs!CP$4,Data!$B$3:$L$3,0)))} -> #N/A | CR27: {=IF(INDEX(Data!$P$4:$Z$947,MATCH(Graphs!$CK27,Data!$A$4:$A$947,0),MATCH(Graphs!CR$4,Data!$P$3:$Z$3,0))="n.q.",NA(),INDEX(Data!$P$4:$Z$947,MATCH(Graphs!$CK27,Data!$A$4:$A$947,0),MATCH(Graphs!CR$4,Data!$P$3:$Z$3,0)))} -> 178.70696 | CS27: {=IF(INDEX(Data!$P$4:$Z$947,MATCH(Graphs!$CK27,Data!$A$4:$A$947,0),MATCH(Graphs!CS$4,Data!$P$3:$Z$3,0))="n.q.",NA(),INDEX(Data!$P$4:$Z$947,MATCH(Graphs!$CK27,Data!$A$4:$A$947,0),MATCH(Graphs!CS$4,Data!$P$3:$Z$3,0)))} -> #N/A | CT27: {=IF(INDEX(Data!$P$4:$Z$947,MATCH(Graphs!$CK27,Data!$A$4:$A$947,0),MATCH(Graphs!CT$4,Data!$P$3:$Z$3,0))="n.q.",NA(),INDEX(Data!$P$4:$Z$947,MATCH(Graphs!$CK27,Data!$A$4:$A$947,0),MATCH(Graphs!CT$4,Data!$P$3:$Z$3,0)))} -> 209.94378 | CU27: {=IF(INDEX(Data!$P$4:$Z$947,MATCH(Graphs!$CK27,Data!$A$4:$A$947,0),MATCH(Graphs!CU$4,Data!$P$3:$Z$3,0))="n.q.",NA(),INDEX(Data!$P$4:$Z$947,MATCH(Graphs!$CK27,Data!$A$4:$A$947,0),MATCH(Graphs!CU$4,Data!$P$3:$Z$3,0)))} -> #N/A | CV27: {=IF(INDEX(Data!$P$4:$Z$947,MATCH(Graphs!$CK27,Data!$A$4:$A$947,0),MATCH(Graphs!CV$4,Data!$P$3:$Z$3,0))="n.q.",NA(),INDEX(Data!$P$4:$Z$947,MATCH(Graphs!$CK27,Data!$A$4:$A$947,0),MATCH(Graphs!CV$4,Data!$P$3:$Z$3,0)))} -> #N/A
CK28: =Data!A27 -> 45805 | CL28: {=IF(INDEX(Data!$B$4:$L$947,MATCH(Graphs!$CK28,Data!$A$4:$A$947,0),MATCH(Graphs!CL$4,Data!$B$3:$L$3,0))="n.q.",NA(),INDEX(Data!$B$4:$L$947,MATCH(Graphs!$CK28,Data!$A$4:$A$947,0),MATCH(Graphs!CL$4,Data!$B$3:$L$3,0)))} -> 229.18 | CM28: {=IF(INDEX(Data!$B$4:$L$947,MATCH(Graphs!$CK28,Data!$A$4:$A$947,0),MATCH(Graphs!CM$4,Data!$B$3:$L$3,0))="n.q.",NA(),INDEX(Data!$B$4:$L$947,MATCH(Graphs!$CK28,Data!$A$4:$A$947,0),MATCH(Graphs!CM$4,Data!$B$3:$L$3,0)))} -> 235.25 | CN28: {=IF(INDEX(Data!$B$4:$L$947,MATCH(Graphs!$CK28,Data!$A$4:$A$947,0),MATCH(Graphs!CN$4,Data!$B$3:$L$3,0))="n.q.",NA(),INDEX(Data!$B$4:$L$947,MATCH(Graphs!$CK28,Data!$A$4:$A$947,0),MATCH(Graphs!CN$4,Data!$B$3:$L$3,0)))} -> 225 | CO28: {=IF(INDEX(Data!$B$4:$L$947,MATCH(Graphs!$CK28,Data!$A$4:$A$947,0),MATCH(Graphs!CO$4,Data!$B$3:$L$3,0))="n.q.",NA(),INDEX(Data!$B$4:$L$947,MATCH(Graphs!$CK28,Data!$A$4:$A$947,0),MATCH(Graphs!CO$4,Data!$B$3:$L$3,0)))} -> #N/A | CP28: {=IF(INDEX(Data!$B$4:$L$947,MATCH(Graphs!$CK28,Data!$A$4:$A$947,0),MATCH(Graphs!CP$4,Data!$B$3:$L$3,0))="n.q.",NA(),INDEX(Data!$B$4:$L$947,MATCH(Graphs!$CK28,Data!$A$4:$A$947,0),MATCH(Graphs!CP$4,Data!$B$3:$L$3,0)))} -> #N/A | CR28: {=IF(INDEX(Data!$P$4:$Z$947,MATCH(Graphs!$CK28,Data!$A$4:$A$947,0),MATCH(Graphs!CR$4,Data!$P$3:$Z$3,0))="n.q.",NA(),INDEX(Data!$P$4:$Z$947,MATCH(Graphs!$CK28,Data!$A$4:$A$947,0),MATCH(Graphs!CR$4,Data!$P$3:$Z$3,0)))} -> 184.02403 | CS28: {=IF(INDEX(Data!$P$4:$Z$947,MATCH(Graphs!$CK28,Data!$A$4:$A$947,0),MATCH(Graphs!CS$4,Data!$P$3:$Z$3,0))="n.q.",NA(),INDEX(Data!$P$4:$Z$947,MATCH(Graphs!$CK28,Data!$A$4:$A$947,0),MATCH(Graphs!CS$4,Data!$P$3:$Z$3,0)))} -> #N/A | CT28: {=IF(INDEX(Data!$P$4:$Z$947,MATCH(Graphs!$CK28,Data!$A$4:$A$947,0),MATCH(Graphs!CT$4,Data!$P$3:$Z$3,0))="n.q.",NA(),INDEX(Data!$P$4:$Z$947,MATCH(Graphs!$CK28,Data!$A$4:$A$947,0),MATCH(Graphs!CT$4,Data!$P$3:$Z$3,0)))} -> 210.30308 | CU28: {=IF(INDEX(Data!$P$4:$Z$947,MATCH(Graphs!$CK28,Data!$A$4:$A$947,0),MATCH(Graphs!CU$4,Data!$P$3:$Z$3,0))="n.q.",NA(),INDEX(Data!$P$4:$Z$947,MATCH(Graphs!$CK28,Data!$A$4:$A$947,0),MATCH(Graphs!CU$4,Data!$P$3:$Z$3,0)))} -> #N/A | CV28: {=IF(INDEX(Data!$P$4:$Z$947,MATCH(Graphs!$CK28,Data!$A$4:$A$947,0),MATCH(Graphs!CV$4,Data!$P$3:$Z$3,0))="n.q.",NA(),INDEX(Data!$P$4:$Z$947,MATCH(Graphs!$CK28,Data!$A$4:$A$947,0),MATCH(Graphs!CV$4,Data!$P$3:$Z$3,0)))} -> #N/A
CK29: =Data!A28 -> 45798 | CL29: {=IF(INDEX(Data!$B$4:$L$947,MATCH(Graphs!$CK29,Data!$A$4:$A$947,0),MATCH(Graphs!CL$4,Data!$B$3:$L$3,0))="n.q.",NA(),INDEX(Data!$B$4:$L$947,MATCH(Graphs!$CK29,Data!$A$4:$A$947,0),MATCH(Graphs!CL$4,Data!$B$3:$L$3,0)))} -> 243.97 | CM29: {=IF(INDEX(Data!$B$4:$L$947,MATCH(Graphs!$CK29,Data!$A$4:$A$947,0),MATCH(Graphs!CM$4,Data!$B$3:$L$3,0))="n.q.",NA(),INDEX(Data!$B$4:$L$947,MATCH(Graphs!$CK29,Data!$A$4:$A$947,0),MATCH(Graphs!CM$4,Data!$B$3:$L$3,0)))} -> 242.69 | CN29: {=IF(INDEX(Data!$B$4:$L$947,MATCH(Graphs!$CK29,Data!$A$4:$A$947,0),MATCH(Graphs!CN$4,Data!$B$3:$L$3,0))="n.q.",NA(),INDEX(Data!$B$4:$L$947,MATCH(Graphs!$CK29,Data!$A$4:$A$947,0),MATCH(Graphs!CN$4,Data!$B$3:$L$3,0)))} -> 235 | CO29: {=IF(INDEX(Data!$B$4:$L$947,MATCH(Graphs!$CK29,Data!$A$4:$A$947,0),MATCH(Graphs!CO$4,Data!$B$3:$L$3,0))="n.q.",NA(),INDEX(Data!$B$4:$L$947,MATCH(Graphs!$CK29,Data!$A$4:$A$947,0),MATCH(Graphs!CO$4,Data!$B$3:$L$3,0)))} -> #N/A | CP29: {=IF(INDEX(Data!$B$4:$L$947,MATCH(Graphs!$CK29,Data!$A$4:$A$947,0),MATCH(Graphs!CP$4,Data!$B$3:$L$3,0))="n.q.",NA(),INDEX(Data!$B$4:$L$947,MATCH(Graphs!$CK29,Data!$A$4:$A$947,0),MATCH(Graphs!CP$4,Data!$B$3:$L$3,0)))} -> #N/A | CR29: {=IF(INDEX(Data!$P$4:$Z$947,MATCH(Graphs!$CK29,Data!$A$4:$A$947,0),MATCH(Graphs!CR$4,Data!$P$3:$Z$3,0))="n.q.",NA(),INDEX(Data!$P$4:$Z$947,MATCH(Graphs!$CK29,Data!$A$4:$A$947,0),MATCH(Graphs!CR$4,Data!$P$3:$Z$3,0)))} -> 187.43044 | CS29: {=IF(INDEX(Data!$P$4:$Z$947,MATCH(Graphs!$CK29,Data!$A$4:$A$947,0),MATCH(Graphs!CS$4,Data!$P$3:$Z$3,0))="n.q.",NA(),INDEX(Data!$P$4:$Z$947,MATCH(Graphs!$CK29,Data!$A$4:$A$947,0),MATCH(Graphs!CS$4,Data!$P$3:$Z$3,0)))} -> #N/A | CT29: {=IF(INDEX(Data!$P$4:$Z$947,MATCH(Graphs!$CK29,Data!$A$4:$A$947,0),MATCH(Graphs!CT$4,Data!$P$3:$Z$3,0))="n.q.",NA(),INDEX(Data!$P$4:$Z$947,MATCH(Graphs!$CK29,Data!$A$4:$A$947,0),MATCH(Graphs!CT$4,Data!$P$3:$Z$3,0)))} -> 213.76204 | CU29: {=IF(INDEX(Data!$P$4:$Z$947,MATCH(Graphs!$CK29,Data!$A$4:$A$947,0),MATCH(Graphs!CU$4,Data!$P$3:$Z$3,0))="n.q.",NA(),INDEX(Data!$P$4:$Z$947,MATCH(Graphs!$CK29,Data!$A$4:$A$947,0),MATCH(Graphs!CU$4,Data!$P$3:$Z$3,0)))} -> #N/A | CV29: {=IF(INDEX(Data!$P$4:$Z$947,MATCH(Graphs!$CK29,Data!$A$4:$A$947,0),MATCH(Graphs!CV$4,Data!$P$3:$Z$3,0))="n.q.",NA(),INDEX(Data!$P$4:$Z$947,MATCH(Graphs!$CK29,Data!$A$4:$A$947,0),MATCH(Graphs!CV$4,Data!$P$3:$Z$3,0)))} -> #N/A
CK30: =Data!A29 -> 45791 | CL30: {=IF(INDEX(Data!$B$4:$L$947,MATCH(Graphs!$CK30,Data!$A$4:$A$947,0),MATCH(Graphs!CL$4,Data!$B$3:$L$3,0))="n.q.",NA(),INDEX(Data!$B$4:$L$947,MATCH(Graphs!$CK30,Data!$A$4:$A$947,0),MATCH(Graphs!CL$4,Data!$B$3:$L$3,0)))} -> 230.37 | CM30: {=IF(INDEX(Data!$B$4:$L$947,MATCH(Graphs!$CK30,Data!$A$4:$A$947,0),MATCH(Graphs!CM$4,Data!$B$3:$L$3,0))="n.q.",NA(),INDEX(Data!$B$4:$L$947,MATCH(Graphs!$CK30,Data!$A$4:$A$947,0),MATCH(Graphs!CM$4,Data!$B$3:$L$3,0)))} -> 234.42 | CN30: {=IF(INDEX(Data!$B$4:$L$947,MATCH(Graphs!$CK30,Data!$A$4:$A$947,0),MATCH(Graphs!CN$4,Data!$B$3:$L$3,0))="n.q.",NA(),INDEX(Data!$B$4:$L$947,MATCH(Graphs!$CK30,Data!$A$4:$A$947,0),MATCH(Graphs!CN$4,Data!$B$3:$L$3,0)))} -> 232 | CO30: {=IF(INDEX(Data!$B$4:$L$947,MATCH(Graphs!$CK30,Data!$A$4:$A$947,0),MATCH(Graphs!CO$4,Data!$B$3:$L$3,0))="n.q.",NA(),INDEX(Data!$B$4:$L$947,MATCH(Graphs!$CK30,Data!$A$4:$A$947,0),MATCH(Graphs!CO$4,Data!$B$3:$L$3,0)))} -> #N/A | CP30: {=IF(INDEX(Data!$B$4:$L$947,MATCH(Graphs!$CK30,Data!$A$4:$A$947,0),MATCH(Graphs!CP$4,Data!$B$3:$L$3,0))="n.q.",NA(),INDEX(Data!$B$4:$L$947,MATCH(Graphs!$CK30,Data!$A$4:$A$947,0),MATCH(Graphs!CP$4,Data!$B$3:$L$3,0)))} -> #N/A | CR30: {=IF(INDEX(Data!$P$4:$Z$947,MATCH(Graphs!$CK30,Data!$A$4:$A$947,0),MATCH(Graphs!CR$4,Data!$P$3:$Z$3,0))="n.q.",NA(),INDEX(Data!$P$4:$Z$947,MATCH(Graphs!$CK30,Data!$A$4:$A$947,0),MATCH(Graphs!CR$4,Data!$P$3:$Z$3,0)))} -> 183.43142 | CS30: {=IF(INDEX(Data!$P$4:$Z$947,MATCH(Graphs!$CK30,Data!$A$4:$A$947,0),MATCH(Graphs!CS$4,Data!$P$3:$Z$3,0))="n.q.",NA(),INDEX(Data!$P$4:$Z$947,MATCH(Graphs!$CK30,Data!$A$4:$A$947,0),MATCH(Graphs!CS$4,Data!$P$3:$Z$3,0)))} -> #N/A | CT30: {=IF(INDEX(Data!$P$4:$Z$947,MATCH(Graphs!$CK30,Data!$A$4:$A$947,0),MATCH(Graphs!CT$4,Data!$P$3:$Z$3,0))="n.q.",NA(),INDEX(Data!$P$4:$Z$947,MATCH(Graphs!$CK30,Data!$A$4:$A$947,0),MATCH(Graphs!CT$4,Data!$P$3:$Z$3,0)))} -> 216.69342 | CU30: {=IF(INDEX(Data!$P$4:$Z$947,MATCH(Graphs!$CK30,Data!$A$4:$A$947,0),MATCH(Graphs!CU$4,Data!$P$3:$Z$3,0))="n.q.",NA(),INDEX(Data!$P$4:$Z$947,MATCH(Graphs!$CK30,Data!$A$4:$A$947,0),MATCH(Graphs!CU$4,Data!$P$3:$Z$3,0)))} -> #N/A | CV30: {=IF(INDEX(Data!$P$4:$Z$947,MATCH(Graphs!$CK30,Data!$A$4:$A$947,0),MATCH(Graphs!CV$4,Data!$P$3:$Z$3,0))="n.q.",NA(),INDEX(Data!$P$4:$Z$947,MATCH(Graphs!$CK30,Data!$A$4:$A$947,0),MATCH(Graphs!CV$4,Data!$P$3:$Z$3,0)))} -> #N/A
CK31: =Data!A30 -> 45784 | CL31: {=IF(INDEX(Data!$B$4:$L$947,MATCH(Graphs!$CK31,Data!$A$4:$A$947,0),MATCH(Graphs!CL$4,Data!$B$3:$L$3,0))="n.q.",NA(),INDEX(Data!$B$4:$L$947,MATCH(Graphs!$CK31,Data!$A$4:$A$947,0),MATCH(Graphs!CL$4,Data!$B$3:$L$3,0)))} -> 233.86 | CM31: {=IF(INDEX(Data!$B$4:$L$947,MATCH(Graphs!$CK31,Data!$A$4:$A$947,0),MATCH(Graphs!CM$4,Data!$B$3:$L$3,0))="n.q.",NA(),INDEX(Data!$B$4:$L$947,MATCH(Graphs!$CK31,Data!$A$4:$A$947,0),MATCH(Graphs!CM$4,Data!$B$3:$L$3,0)))} -> 238.65 | CN31: {=IF(INDEX(Data!$B$4:$L$947,MATCH(Graphs!$CK31,Data!$A$4:$A$947,0),MATCH(Graphs!CN$4,Data!$B$3:$L$3,0))="n.q.",NA(),INDEX(Data!$B$4:$L$947,MATCH(Graphs!$CK31,Data!$A$4:$A$947,0),MATCH(Graphs!CN$4,Data!$B$3:$L$3,0)))} -> 234 | CO31: {=IF(INDEX(Data!$B$4:$L$947,MATCH(Graphs!$CK31,Data!$A$4:$A$947,0),MATCH(Graphs!CO$4,Data!$B$3:$L$3,0))="n.q.",NA(),INDEX(Data!$B$4:$L$947,MATCH(Graphs!$CK31,Data!$A$4:$A$947,0),MATCH(Graphs!CO$4,Data!$B$3:$L$3,0)))} -> #N/A | CP31: {=IF(INDEX(Data!$B$4:$L$947,MATCH(Graphs!$CK31,Data!$A$4:$A$947,0),MATCH(Graphs!CP$4,Data!$B$3:$L$3,0))="n.q.",NA(),INDEX(Data!$B$4:$L$947,MATCH(Graphs!$CK31,Data!$A$4:$A$947,0),MATCH(Graphs!CP$4,Data!$B$3:$L$3,0)))} -> #N/A | CR31: {=IF(INDEX(Data!$P$4:$Z$947,MATCH(Graphs!$CK31,Data!$A$4:$A$947,0),MATCH(Graphs!CR$4,Data!$P$3:$Z$3,0))="n.q.",NA(),INDEX(Data!$P$4:$Z$947,MATCH(Graphs!$CK31,Data!$A$4:$A$947,0),MATCH(Graphs!CR$4,Data!$P$3:$Z$3,0)))} -> 182.72007 | CS31: {=IF(INDEX(Data!$P$4:$Z$947,MATCH(Graphs!$CK31,Data!$A$4:$A$947,0),MATCH(Graphs!CS$4,Data!$P$3:$Z$3,0))="n.q.",NA(),INDEX(Data!$P$4:$Z$947,MATCH(Graphs!$CK31,Data!$A$4:$A$947,0),MATCH(Graphs!CS$4,Data!$P$3:$Z$3,0)))} -> #N/A | CT31: {=IF(INDEX(Data!$P$4:$Z$947,MATCH(Graphs!$CK31,Data!$A$4:$A$947,0),MATCH(Graphs!CT$4,Data!$P$3:$Z$3,0))="n.q.",NA(),INDEX(Data!$P$4:$Z$947,MATCH(Graphs!$CK31,Data!$A$4:$A$947,0),MATCH(Graphs!CT$4,Data!$P$3:$Z$3,0)))} -> 218.30986 | CU31: {=IF(INDEX(Data!$P$4:$Z$947,MATCH(Graphs!$CK31,Data!$A$4:$A$947,0),MATCH(Graphs!CU$4,Data!$P$3:$Z$3,0))="n.q.",NA(),INDEX(Data!$P$4:$Z$947,MATCH(Graphs!$CK31,Data!$A$4:$A$947,0),MATCH(Graphs!CU$4,Data!$P$3:$Z$3,0)))} -> #N/A | CV31: {=IF(INDEX(Data!$P$4:$Z$947,MATCH(Graphs!$CK31,Data!$A$4:$A$947,0),MATCH(Graphs!CV$4,Data!$P$3:$Z$3,0))="n.q.",NA(),INDEX(Data!$P$4:$Z$947,MATCH(Graphs!$CK31,Data!$A$4:$A$947,0),MATCH(Graphs!CV$4,Data!$P$3:$Z$3,0)))} -> #N/A
CK32: =Data!A31 -> 45777 | CL32: {=IF(INDEX(Data!$B$4:$L$947,MATCH(Graphs!$CK32,Data!$A$4:$A$947,0),MATCH(Graphs!CL$4,Data!$B$3:$L$3,0))="n.q.",NA(),INDEX(Data!$B$4:$L$947,MATCH(Graphs!$CK32,Data!$A$4:$A$947,0),MATCH(Graphs!CL$4,Data!$B$3:$L$3,0)))} -> 236.21 | CM32: {=IF(INDEX(Data!$B$4:$L$947,MATCH(Graphs!$CK32,Data!$A$4:$A$947,0),MATCH(Graphs!CM$4,Data!$B$3:$L$3,0))="n.q.",NA(),INDEX(Data!$B$4:$L$947,MATCH(Graphs!$CK32,Data!$A$4:$A$947,0),MATCH(Graphs!CM$4,Data!$B$3:$L$3,0)))} -> 238.65 | CN32: {=IF(INDEX(Data!$B$4:$L$947,MATCH(Graphs!$CK32,Data!$A$4:$A$947,0),MATCH(Graphs!CN$4,Data!$B$3:$L$3,0))="n.q.",NA(),INDEX(Data!$B$4:$L$947,MATCH(Graphs!$CK32,Data!$A$4:$A$947,0),MATCH(Graphs!CN$4,Data!$B$3:$L$3,0)))} -> 234 | CO32: {=IF(INDEX(Data!$B$4:$L$947,MATCH(Graphs!$CK32,Data!$A$4:$A$947,0),MATCH(Graphs!CO$4,Data!$B$3:$L$3,0))="n.q.",NA(),INDEX(Data!$B$4:$L$947,MATCH(Graphs!$CK32,Data!$A$4:$A$947,0),MATCH(Graphs!CO$4,Data!$B$3:$L$3,0)))} -> #N/A | CP32: {=IF(INDEX(Data!$B$4:$L$947,MATCH(Graphs!$CK32,Data!$A$4:$A$947,0),MATCH(Graphs!CP$4,Data!$B$3:$L$3,0))="n.q.",NA(),INDEX(Data!$B$4:$L$947,MATCH(Graphs!$CK32,Data!$A$4:$A$947,0),MATCH(Graphs!CP$4,Data!$B$3:$L$3,0)))} -> #N/A | CR32: {=IF(INDEX(Data!$P$4:$Z$947,MATCH(Graphs!$CK32,Data!$A$4:$A$947,0),MATCH(Graphs!CR$4,Data!$P$3:$Z$3,0))="n.q.",NA(),INDEX(Data!$P$4:$Z$947,MATCH(Graphs!$CK32,Data!$A$4:$A$947,0),MATCH(Graphs!CR$4,Data!$P$3:$Z$3,0)))} -> 189.51904 | CS32: {=IF(INDEX(Data!$P$4:$Z$947,MATCH(Graphs!$CK32,Data!$A$4:$A$947,0),MATCH(Graphs!CS$4,Data!$P$3:$Z$3,0))="n.q.",NA(),INDEX(Data!$P$4:$Z$947,MATCH(Graphs!$CK32,Data!$A$4:$A$947,0),MATCH(Graphs!CS$4,Data!$P$3:$Z$3,0)))} -> #N/A | CT32: {=IF(INDEX(Data!$P$4:$Z$947,MATCH(Graphs!$CK32,Data!$A$4:$A$947,0),MATCH(Graphs!CT$4,Data!$P$3:$Z$3,0))="n.q.",NA(),INDEX(Data!$P$4:$Z$947,MATCH(Graphs!$CK32,Data!$A$4:$A$947,0),MATCH(Graphs!CT$4,Data!$P$3:$Z$3,0)))} -> 218.93959 | CU32: {=IF(INDEX(Data!$P$4:$Z$947,MATCH(Graphs!$CK32,Data!$A$4:$A$947,0),MATCH(Graphs!CU$4,Data!$P$3:$Z$3,0))="n.q.",NA(),INDEX(Data!$P$4:$Z$947,MATCH(Graphs!$CK32,Data!$A$4:$A$947,0),MATCH(Graphs!CU$4,Data!$P$3:$Z$3,0)))} -> #N/A | CV32: {=IF(INDEX(Data!$P$4:$Z$947,MATCH(Graphs!$CK32,Data!$A$4:$A$947,0),MATCH(Graphs!CV$4,Data!$P$3:$Z$3,0))="n.q.",NA(),INDEX(Data!$P$4:$Z$947,MATCH(Graphs!$CK32,Data!$A$4:$A$947,0),MATCH(Graphs!CV$4,Data!$P$3:$Z$3,0)))} -> #N/A
CK33: =Data!A32 -> 45770 | CL33: {=IF(INDEX(Data!$B$4:$L$947,MATCH(Graphs!$CK33,Data!$A$4:$A$947,0),MATCH(Graphs!CL$4,Data!$B$3:$L$3,0))="n.q.",NA(),INDEX(Data!$B$4:$L$947,MATCH(Graphs!$CK33,Data!$A$4:$A$947,0),MATCH(Graphs!CL$4,Data!$B$3:$L$3,0)))} -> 240.71 | CM33: {=IF(INDEX(Data!$B$4:$L$947,MATCH(Graphs!$CK33,Data!$A$4:$A$947,0),MATCH(Graphs!CM$4,Data!$B$3:$L$3,0))="n.q.",NA(),INDEX(Data!$B$4:$L$947,MATCH(Graphs!$CK33,Data!$A$4:$A$947,0),MATCH(Graphs!CM$4,Data!$B$3:$L$3,0)))} -> 245.36 | CN33: {=IF(INDEX(Data!$B$4:$L$947,MATCH(Graphs!$CK33,Data!$A$4:$A$947,0),MATCH(Graphs!CN$4,Data!$B$3:$L$3,0))="n.q.",NA(),INDEX(Data!$B$4:$L$947,MATCH(Graphs!$CK33,Data!$A$4:$A$947,0),MATCH(Graphs!CN$4,Data!$B$3:$L$3,0)))} -> 235 | CO33: {=IF(INDEX(Data!$B$4:$L$947,MATCH(Graphs!$CK33,Data!$A$4:$A$947,0),MATCH(Graphs!CO$4,Data!$B$3:$L$3,0))="n.q.",NA(),INDEX(Data!$B$4:$L$947,MATCH(Graphs!$CK33,Data!$A$4:$A$947,0),MATCH(Graphs!CO$4,Data!$B$3:$L$3,0)))} -> #N/A | CP33: {=IF(INDEX(Data!$B$4:$L$947,MATCH(Graphs!$CK33,Data!$A$4:$A$947,0),MATCH(Graphs!CP$4,Data!$B$3:$L$3,0))="n.q.",NA(),INDEX(Data!$B$4:$L$947,MATCH(Graphs!$CK33,Data!$A$4:$A$947,0),MATCH(Graphs!CP$4,Data!$B$3:$L$3,0)))} -> #N/A | CR33: {=IF(INDEX(Data!$P$4:$Z$947,MATCH(Graphs!$CK33,Data!$A$4:$A$947,0),MATCH(Graphs!CR$4,Data!$P$3:$Z$3,0))="n.q.",NA(),INDEX(Data!$P$4:$Z$947,MATCH(Graphs!$CK33,Data!$A$4:$A$947,0),MATCH(Graphs!CR$4,Data!$P$3:$Z$3,0)))} -> 190.72273 | CS33: {=IF(INDEX(Data!$P$4:$Z$947,MATCH(Graphs!$CK33,Data!$A$4:$A$947,0),MATCH(Graphs!CS$4,Data!$P$3:$Z$3,0))="n.q.",NA(),INDEX(Data!$P$4:$Z$947,MATCH(Graphs!$CK33,Data!$A$4:$A$947,0),MATCH(Graphs!CS$4,Data!$P$3:$Z$3,0)))} -> #N/A | CT33: {=IF(INDEX(Data!$P$4:$Z$947,MATCH(Graphs!$CK33,Data!$A$4:$A$947,0),MATCH(Graphs!CT$4,Data!$P$3:$Z$3,0))="n.q.",NA(),INDEX(Data!$P$4:$Z$947,MATCH(Graphs!$CK33,Data!$A$4:$A$947,0),MATCH(Graphs!CT$4,Data!$P$3:$Z$3,0)))} -> 212.87779 | CU33: {=IF(INDEX(Data!$P$4:$Z$947,MATCH(Graphs!$CK33,Data!$A$4:$A$947,0),MATCH(Graphs!CU$4,Data!$P$3:$Z$3,0))="n.q.",NA(),INDEX(Data!$P$4:$Z$947,MATCH(Graphs!$CK33,Data!$A$4:$A$947,0),MATCH(Graphs!CU$4,Data!$P$3:$Z$3,0)))} -> #N/A | CV33: {=IF(INDEX(Data!$P$4:$Z$947,MATCH(Graphs!$CK33,Data!$A$4:$A$947,0),MATCH(Graphs!CV$4,Data!$P$3:$Z$3,0))="n.q.",NA(),INDEX(Data!$P$4:$Z$947,MATCH(Graphs!$CK33,Data!$A$4:$A$947,0),MATCH(Graphs!CV$4,Data!$P$3:$Z$3,0)))} -> #N/A
CK34: =Data!A33 -> 45763 | CL34: {=IF(INDEX(Data!$B$4:$L$947,MATCH(Graphs!$CK34,Data!$A$4:$A$947,0),MATCH(Graphs!CL$4,Data!$B$3:$L$3,0))="n.q.",NA(),INDEX(Data!$B$4:$L$947,MATCH(Graphs!$CK34,Data!$A$4:$A$947,0),MATCH(Graphs!CL$4,Data!$B$3:$L$3,0)))} -> 243.77 | CM34: {=IF(INDEX(Data!$B$4:$L$947,MATCH(Graphs!$CK34,Data!$A$4:$A$947,0),MATCH(Graphs!CM$4,Data!$B$3:$L$3,0))="n.q.",NA(),INDEX(Data!$B$4:$L$947,MATCH(Graphs!$CK34,Data!$A$4:$A$947,0),MATCH(Graphs!CM$4,Data!$B$3:$L$3,0)))} -> 250.96 | CN34: {=IF(INDEX(Data!$B$4:$L$947,MATCH(Graphs!$CK34,Data!$A$4:$A$947,0),MATCH(Graphs!CN$4,Data!$B$3:$L$3,0))="n.q.",NA(),INDEX(Data!$B$4:$L$947,MATCH(Graphs!$CK34,Data!$A$4:$A$947,0),MATCH(Graphs!CN$4,Data!$B$3:$L$3,0)))} -> 234 | CO34: {=IF(INDEX(Data!$B$4:$L$947,MATCH(Graphs!$CK34,Data!$A$4:$A$947,0),MATCH(Graphs!CO$4,Data!$B$3:$L$3,0))="n.q.",NA(),INDEX(Data!$B$4:$L$947,MATCH(Graphs!$CK34,Data!$A$4:$A$947,0),MATCH(Graphs!CO$4,Data!$B$3:$L$3,0)))} -> #N/A | CP34: {=IF(INDEX(Data!$B$4:$L$947,MATCH(Graphs!$CK34,Data!$A$4:$A$947,0),MATCH(Graphs!CP$4,Data!$B$3:$L$3,0))="n.q.",NA(),INDEX(Data!$B$4:$L$947,MATCH(Graphs!$CK34,Data!$A$4:$A$947,0),MATCH(Graphs!CP$4,Data!$B$3:$L$3,0)))} -> #N/A | CR34: {=IF(INDEX(Data!$P$4:$Z$947,MATCH(Graphs!$CK34,Data!$A$4:$A$947,0),MATCH(Graphs!CR$4,Data!$P$3:$Z$3,0))="n.q.",NA(),INDEX(Data!$P$4:$Z$947,MATCH(Graphs!$CK34,Data!$A$4:$A$947,0),MATCH(Graphs!CR$4,Data!$P$3:$Z$3,0)))} -> 197.35799 | CS34: {=IF(INDEX(Data!$P$4:$Z$947,MATCH(Graphs!$CK34,Data!$A$4:$A$947,0),MATCH(Graphs!CS$4,Data!$P$3:$Z$3,0))="n.q.",NA(),INDEX(Data!$P$4:$Z$947,MATCH(Graphs!$CK34,Data!$A$4:$A$947,0),MATCH(Graphs!CS$4,Data!$P$3:$Z$3,0)))} -> #N/A | CT34: {=IF(INDEX(Data!$P$4:$Z$947,MATCH(Graphs!$CK34,Data!$A$4:$A$947,0),MATCH(Graphs!CT$4,Data!$P$3:$Z$3,0))="n.q.",NA(),INDEX(Data!$P$4:$Z$947,MATCH(Graphs!$CK34,Data!$A$4:$A$947,0),MATCH(Graphs!CT$4,Data!$P$3:$Z$3,0)))} -> 213.12197 | CU34: {=IF(INDEX(Data!$P$4:$Z$947,MATCH(Graphs!$CK34,Data!$A$4:$A$947,0),MATCH(Graphs!CU$4,Data!$P$3:$Z$3,0))="n.q.",NA(),INDEX(Data!$P$4:$Z$947,MATCH(Graphs!$CK34,Data!$A$4:$A$947,0),MATCH(Graphs!CU$4,Data!$P$3:$Z$3,0)))} -> #N/A | CV34: {=IF(INDEX(Data!$P$4:$Z$947,MATCH(Graphs!$CK34,Data!$A$4:$A$947,0),MATCH(Graphs!CV$4,Data!$P$3:$Z$3,0))="n.q.",NA(),INDEX(Data!$P$4:$Z$947,MATCH(Graphs!$CK34,Data!$A$4:$A$947,0),MATCH(Graphs!CV$4,Data!$P$3:$Z$3,0)))} -> #N/A
CK35: =Data!A34 -> 45756 | CL35: {=IF(INDEX(Data!$B$4:$L$947,MATCH(Graphs!$CK35,Data!$A$4:$A$947,0),MATCH(Graphs!CL$4,Data!$B$3:$L$3,0))="n.q.",NA(),INDEX(Data!$B$4:$L$947,MATCH(Graphs!$CK35,Data!$A$4:$A$947,0),MATCH(Graphs!CL$4,Data!$B$3:$L$3,0)))} -> 247.44 | CM35: {=IF(INDEX(Data!$B$4:$L$947,MATCH(Graphs!$CK35,Data!$A$4:$A$947,0),MATCH(Graphs!CM$4,Data!$B$3:$L$3,0))="n.q.",NA(),INDEX(Data!$B$4:$L$947,MATCH(Graphs!$CK35,Data!$A$4:$A$947,0),MATCH(Graphs!CM$4,Data!$B$3:$L$3,0)))} -> 254.63 | CN35: {=IF(INDEX(Data!$B$4:$L$947,MATCH(Graphs!$CK35,Data!$A$4:$A$947,0),MATCH(Graphs!CN$4,Data!$B$3:$L$3,0))="n.q.",NA(),INDEX(Data!$B$4:$L$947,MATCH(Graphs!$CK35,Data!$A$4:$A$947,0),MATCH(Graphs!CN$4,Data!$B$3:$L$3,0)))} -> 234 | CO35: {=IF(INDEX(Data!$B$4:$L$947,MATCH(Graphs!$CK35,Data!$A$4:$A$947,0),MATCH(Graphs!CO$4,Data!$B$3:$L$3,0))="n.q.",NA(),INDEX(Data!$B$4:$L$947,MATCH(Graphs!$CK35,Data!$A$4:$A$947,0),MATCH(Graphs!CO$4,Data!$B$3:$L$3,0)))} -> #N/A | CP35: {=IF(INDEX(Data!$B$4:$L$947,MATCH(Graphs!$CK35,Data!$A$4:$A$947,0),MATCH(Graphs!CP$4,Data!$B$3:$L$3,0))="n.q.",NA(),INDEX(Data!$B$4:$L$947,MATCH(Graphs!$CK35,Data!$A$4:$A$947,0),MATCH(Graphs!CP$4,Data!$B$3:$L$3,0)))} -> #N/A | CR35: {=IF(INDEX(Data!$P$4:$Z$947,MATCH(Graphs!$CK35,Data!$A$4:$A$947,0),MATCH(Graphs!CR$4,Data!$P$3:$Z$3,0))="n.q.",NA(),INDEX(Data!$P$4:$Z$947,MATCH(Graphs!$CK35,Data!$A$4:$A$947,0),MATCH(Graphs!CR$4,Data!$P$3:$Z$3,0)))} -> 198.53327 | CS35: {=IF(INDEX(Data!$P$4:$Z$947,MATCH(Graphs!$CK35,Data!$A$4:$A$947,0),MATCH(Graphs!CS$4,Data!$P$3:$Z$3,0))="n.q.",NA(),INDEX(Data!$P$4:$Z$947,MATCH(Graphs!$CK35,Data!$A$4:$A$947,0),MATCH(Graphs!CS$4,Data!$P$3:$Z$3,0)))} -> #N/A | CT35: {=IF(INDEX(Data!$P$4:$Z$947,MATCH(Graphs!$CK35,Data!$A$4:$A$947,0),MATCH(Graphs!CT$4,Data!$P$3:$Z$3,0))="n.q.",NA(),INDEX(Data!$P$4:$Z$947,MATCH(Graphs!$CK35,Data!$A$4:$A$947,0),MATCH(Graphs!CT$4,Data!$P$3:$Z$3,0)))} -> 219.10367 | CU35: {=IF(INDEX(Data!$P$4:$Z$947,MATCH(Graphs!$CK35,Data!$A$4:$A$947,0),MATCH(Graphs!CU$4,Data!$P$3:$Z$3,0))="n.q.",NA(),INDEX(Data!$P$4:$Z$947,MATCH(Graphs!$CK35,Data!$A$4:$A$947,0),MATCH(Graphs!CU$4,Data!$P$3:$Z$3,0)))} -> #N/A | CV35: {=IF(INDEX(Data!$P$4:$Z$947,MATCH(Graphs!$CK35,Data!$A$4:$A$947,0),MATCH(Graphs!CV$4,Data!$P$3:$Z$3,0))="n.q.",NA(),INDEX(Data!$P$4:$Z$947,MATCH(Graphs!$CK35,Data!$A$4:$A$947,0),MATCH(Graphs!CV$4,Data!$P$3:$Z$3,0)))} -> #N/A
CK36: =Data!A35 -> 45749 | CL36: {=IF(INDEX(Data!$B$4:$L$947,MATCH(Graphs!$CK36,Data!$A$4:$A$947,0),MATCH(Graphs!CL$4,Data!$B$3:$L$3,0))="n.q.",NA(),INDEX(Data!$B$4:$L$947,MATCH(Graphs!$CK36,Data!$A$4:$A$947,0),MATCH(Graphs!CL$4,Data!$B$3:$L$3,0)))} -> 243.61 | CM36: {=IF(INDEX(Data!$B$4:$L$947,MATCH(Graphs!$CK36,Data!$A$4:$A$947,0),MATCH(Graphs!CM$4,Data!$B$3:$L$3,0))="n.q.",NA(),INDEX(Data!$B$4:$L$947,MATCH(Graphs!$CK36,Data!$A$4:$A$947,0),MATCH(Graphs!CM$4,Data!$B$3:$L$3,0)))} -> 254.82 | CN36: {=IF(INDEX(Data!$B$4:$L$947,MATCH(Graphs!$CK36,Data!$A$4:$A$947,0),MATCH(Graphs!CN$4,Data!$B$3:$L$3,0))="n.q.",NA(),INDEX(Data!$B$4:$L$947,MATCH(Graphs!$CK36,Data!$A$4:$A$947,0),MATCH(Graphs!CN$4,Data!$B$3:$L$3,0)))} -> 236 | CO36: {=IF(INDEX(Data!$B$4:$L$947,MATCH(Graphs!$CK36,Data!$A$4:$A$947,0),MATCH(Graphs!CO$4,Data!$B$3:$L$3,0))="n.q.",NA(),INDEX(Data!$B$4:$L$947,MATCH(Graphs!$CK36,Data!$A$4:$A$947,0),MATCH(Graphs!CO$4,Data!$B$3:$L$3,0)))} -> #N/A | CP36: {=IF(INDEX(Data!$B$4:$L$947,MATCH(Graphs!$CK36,Data!$A$4:$A$947,0),MATCH(Graphs!CP$4,Data!$B$3:$L$3,0))="n.q.",NA(),INDEX(Data!$B$4:$L$947,MATCH(Graphs!$CK36,Data!$A$4:$A$947,0),MATCH(Graphs!CP$4,Data!$B$3:$L$3,0)))} -> #N/A | CR36: {=IF(INDEX(Data!$P$4:$Z$947,MATCH(Graphs!$CK36,Data!$A$4:$A$947,0),MATCH(Graphs!CR$4,Data!$P$3:$Z$3,0))="n.q.",NA(),INDEX(Data!$P$4:$Z$947,MATCH(Graphs!$CK36,Data!$A$4:$A$947,0),MATCH(Graphs!CR$4,Data!$P$3:$Z$3,0)))} -> 195.24206 | CS36: {=IF(INDEX(Data!$P$4:$Z$947,MATCH(Graphs!$CK36,Data!$A$4:$A$947,0),MATCH(Graphs!CS$4,Data!$P$3:$Z$3,0))="n.q.",NA(),INDEX(Data!$P$4:$Z$947,MATCH(Graphs!$CK36,Data!$A$4:$A$947,0),MATCH(Graphs!CS$4,Data!$P$3:$Z$3,0)))} -> #N/A | CT36: {=IF(INDEX(Data!$P$4:$Z$947,MATCH(Graphs!$CK36,Data!$A$4:$A$947,0),MATCH(Graphs!CT$4,Data!$P$3:$Z$3,0))="n.q.",NA(),INDEX(Data!$P$4:$Z$947,MATCH(Graphs!$CK36,Data!$A$4:$A$947,0),MATCH(Graphs!CT$4,Data!$P$3:$Z$3,0)))} -> 221.23484 | CU36: {=IF(INDEX(Data!$P$4:$Z$947,MATCH(Graphs!$CK36,Data!$A$4:$A$947,0),MATCH(Graphs!CU$4,Data!$P$3:$Z$3,0))="n.q.",NA(),INDEX(Data!$P$4:$Z$947,MATCH(Graphs!$CK36,Data!$A$4:$A$947,0),MATCH(Graphs!CU$4,Data!$P$3:$Z$3,0)))} -> #N/A | CV36: {=IF(INDEX(Data!$P$4:$Z$947,MATCH(Graphs!$CK36,Data!$A$4:$A$947,0),MATCH(Graphs!CV$4,Data!$P$3:$Z$3,0))="n.q.",NA(),INDEX(Data!$P$4:$Z$947,MATCH(Graphs!$CK36,Data!$A$4:$A$947,0),MATCH(Graphs!CV$4,Data!$P$3:$Z$3,0)))} -> #N/A
CK37: =Data!A36 -> 45742 | CL37: {=IF(INDEX(Data!$B$4:$L$947,MATCH(Graphs!$CK37,Data!$A$4:$A$947,0),MATCH(Graphs!CL$4,Data!$B$3:$L$3,0))="n.q.",NA(),INDEX(Data!$B$4:$L$947,MATCH(Graphs!$CK37,Data!$A$4:$A$947,0),MATCH(Graphs!CL$4,Data!$B$3:$L$3,0)))} -> 240.81 | CM37: {=IF(INDEX(Data!$B$4:$L$947,MATCH(Graphs!$CK37,Data!$A$4:$A$947,0),MATCH(Graphs!CM$4,Data!$B$3:$L$3,0))="n.q.",NA(),INDEX(Data!$B$4:$L$947,MATCH(Graphs!$CK37,Data!$A$4:$A$947,0),MATCH(Graphs!CM$4,Data!$B$3:$L$3,0)))} -> 253.53 | CN37: {=IF(INDEX(Data!$B$4:$L$947,MATCH(Graphs!$CK37,Data!$A$4:$A$947,0),MATCH(Graphs!CN$4,Data!$B$3:$L$3,0))="n.q.",NA(),INDEX(Data!$B$4:$L$947,MATCH(Graphs!$CK37,Data!$A$4:$A$947,0),MATCH(Graphs!CN$4,Data!$B$3:$L$3,0)))} -> 237 | CO37: {=IF(INDEX(Data!$B$4:$L$947,MATCH(Graphs!$CK37,Data!$A$4:$A$947,0),MATCH(Graphs!CO$4,Data!$B$3:$L$3,0))="n.q.",NA(),INDEX(Data!$B$4:$L$947,MATCH(Graphs!$CK37,Data!$A$4:$A$947,0),MATCH(Graphs!CO$4,Data!$B$3:$L$3,0)))} -> #N/A | CP37: {=IF(INDEX(Data!$B$4:$L$947,MATCH(Graphs!$CK37,Data!$A$4:$A$947,0),MATCH(Graphs!CP$4,Data!$B$3:$L$3,0))="n.q.",NA(),INDEX(Data!$B$4:$L$947,MATCH(Graphs!$CK37,Data!$A$4:$A$947,0),MATCH(Graphs!CP$4,Data!$B$3:$L$3,0)))} -> #N/A | CR37: {=IF(INDEX(Data!$P$4:$Z$947,MATCH(Graphs!$CK37,Data!$A$4:$A$947,0),MATCH(Graphs!CR$4,Data!$P$3:$Z$3,0))="n.q.",NA(),INDEX(Data!$P$4:$Z$947,MATCH(Graphs!$CK37,Data!$A$4:$A$947,0),MATCH(Graphs!CR$4,Data!$P$3:$Z$3,0)))} -> 191.31442 | CS37: {=IF(INDEX(Data!$P$4:$Z$947,MATCH(Graphs!$CK37,Data!$A$4:$A$947,0),MATCH(Graphs!CS$4,Data!$P$3:$Z$3,0))="n.q.",NA(),INDEX(Data!$P$4:$Z$947,MATCH(Graphs!$CK37,Data!$A$4:$A$947,0),MATCH(Graphs!CS$4,Data!$P$3:$Z$3,0)))} -> #N/A | CT37: {=IF(INDEX(Data!$P$4:$Z$947,MATCH(Graphs!$CK37,Data!$A$4:$A$947,0),MATCH(Graphs!CT$4,Data!$P$3:$Z$3,0))="n.q.",NA(),INDEX(Data!$P$4:$Z$947,MATCH(Graphs!$CK37,Data!$A$4:$A$947,0),MATCH(Graphs!CT$4,Data!$P$3:$Z$3,0)))} -> 219.68854 | CU37: {=IF(INDEX(Data!$P$4:$Z$947,MATCH(Graphs!$CK37,Data!$A$4:$A$947,0),MATCH(Graphs!CU$4,Data!$P$3:$Z$3,0))="n.q.",NA(),INDEX(Data!$P$4:$Z$947,MATCH(Graphs!$CK37,Data!$A$4:$A$947,0),MATCH(Graphs!CU$4,Data!$P$3:$Z$3,0)))} -> #N/A | CV37: {=IF(INDEX(Data!$P$4:$Z$947,MATCH(Graphs!$CK37,Data!$A$4:$A$947,0),MATCH(Graphs!CV$4,Data!$P$3:$Z$3,0))="n.q.",NA(),INDEX(Data!$P$4:$Z$947,MATCH(Graphs!$CK37,Data!$A$4:$A$947,0),MATCH(Graphs!CV$4,Data!$P$3:$Z$3,0)))} -> #N/A
